<sdf version='1.6'>
  <world name='default'>
    <light name='sun' type='directional'>
      <cast_shadows>0</cast_shadows>
      <pose frame=''>0 0 10 0 -0 0</pose>
      <diffuse>0.8 0.8 0.8 1</diffuse>
      <specular>0.1 0.1 0.1 1</specular>
      <attenuation>
        <range>1000</range>
        <constant>0.9</constant>
        <linear>0.01</linear>
        <quadratic>0.001</quadratic>
      </attenuation>
      <direction>-0.5 0.5 -1</direction>
    </light>
    <model name='ground_plane'>
      <static>1</static>
      <link name='link'>
        <collision name='collision'>
          <geometry>
            <plane>
              <normal>0 0 1</normal>
              <size>100 100</size>
            </plane>
          </geometry>
          <surface>
            <friction>
              <ode>
                <mu>100</mu>
                <mu2>50</mu2>
              </ode>
              <torsional>
                <ode/>
              </torsional>
            </friction>
            <contact>
              <ode/>
            </contact>
            <bounce/>
          </surface>
          <max_contacts>10</max_contacts>
        </collision>
        <visual name='visual'>
          <cast_shadows>0</cast_shadows>
          <geometry>
            <plane>
              <normal>0 0 1</normal>
              <size>100 100</size>
            </plane>
          </geometry>
          <material>
            <script>
              <uri>file://media/materials/scripts/gazebo.material</uri>
              <name>Gazebo/Grey</name>
            </script>
          </material>
        </visual>
        <self_collide>0</self_collide>
        <kinematic>0</kinematic>
        <gravity>1</gravity>
      </link>
    </model>
    <gravity>0 0 -9.8</gravity>
    <magnetic_field>6e-06 2.3e-05 -4.2e-05</magnetic_field>
    <atmosphere type='adiabatic'/>
    <physics name='default_physics' default='0' type='ode'>
      <max_step_size>0.001</max_step_size>
      <real_time_factor>1</real_time_factor>
      <real_time_update_rate>1000</real_time_update_rate>
    </physics>
    <scene>
      <ambient>0.4 0.4 0.4 1</ambient>
      <background>0.7 0.7 0.7 1</background>
      <shadows>1</shadows>
    </scene>
    <spherical_coordinates>
      <surface_model>EARTH_WGS84</surface_model>
      <latitude_deg>0</latitude_deg>
      <longitude_deg>0</longitude_deg>
      <elevation>0</elevation>
      <heading_deg>0</heading_deg>
    </spherical_coordinates>
    <state world_name='default'>
      <sim_time>4781 151000000</sim_time>
      <real_time>1613 212592386</real_time>
      <wall_time>1554151642 183867636</wall_time>
      <iterations>1536121</iterations>
      <model name='Stop Sign'>
        <pose frame=''>8.27709 5.20939 0 0 -0 0</pose>
        <scale>1 1 1</scale>
        <link name='link'>
          <pose frame=''>8.27709 5.20939 0 0 -0 0</pose>
          <velocity>0 0 0 0 -0 0</velocity>
          <acceleration>0 0 0 0 -0 0</acceleration>
          <wrench>0 0 0 0 -0 0</wrench>
        </link>
      </model>
      <model name='car'>
        <pose frame=''>1.79596 -5.96117 0 0 -0 0</pose>
        <scale>1 1 1</scale>
        <link name='back_left_wheel'>
          <pose frame=''>0.99596 -5.36117 0.3 -0 1.5707 1.5707</pose>
          <velocity>0 0 0 0 -0 0</velocity>
          <acceleration>0 0 0 0 -0 0</acceleration>
          <wrench>0 0 0 0 -0 0</wrench>
        </link>
        <link name='back_right_wheel'>
          <pose frame=''>0.99596 -6.56117 0.3 -0 1.5707 1.5707</pose>
          <velocity>0 0 0 0 -0 0</velocity>
          <acceleration>0 0 0 0 -0 0</acceleration>
          <wrench>0 0 0 0 -0 0</wrench>
        </link>
        <link name='brake_pedal'>
          <pose frame=''>2.09596 -5.71117 0.5 0 -0 0</pose>
          <velocity>0 0 0 0 -0 0</velocity>
          <acceleration>0 0 0 0 -0 0</acceleration>
          <wrench>0 0 0 0 -0 0</wrench>
        </link>
        <link name='chassis'>
          <pose frame=''>1.79596 -5.96117 0.3 0 -0 0</pose>
          <velocity>0 0 0 0 -0 0</velocity>
          <acceleration>0 0 0 0 -0 0</acceleration>
          <wrench>0 0 0 0 -0 0</wrench>
        </link>
        <link name='front_left_wheel'>
          <pose frame=''>2.59596 -5.36117 0.3 -0 1.5707 1.5707</pose>
          <velocity>0 0 0 0 -0 0</velocity>
          <acceleration>0 0 0 0 -0 0</acceleration>
          <wrench>0 0 0 0 -0 0</wrench>
        </link>
        <link name='front_right_wheel'>
          <pose frame=''>2.59596 -6.56117 0.3 -0 1.5707 1.5707</pose>
          <velocity>0 0 0 0 -0 0</velocity>
          <acceleration>0 0 0 0 -0 0</acceleration>
          <wrench>0 0 0 0 -0 0</wrench>
        </link>
        <link name='gas_pedal'>
          <pose frame=''>2.09596 -5.86117 0.5 0 -0 0</pose>
          <velocity>0 0 0 0 -0 0</velocity>
          <acceleration>0 0 0 0 -0 0</acceleration>
          <wrench>0 0 0 0 -0 0</wrench>
        </link>
        <link name='steering_wheel'>
          <pose frame=''>2.09596 -5.76117 1 0 1.5707 0</pose>
          <velocity>0 0 0 0 -0 0</velocity>
          <acceleration>0 0 0 0 -0 0</acceleration>
          <wrench>0 0 0 0 -0 0</wrench>
        </link>
      </model>
      <model name='ground_plane'>
        <pose frame=''>0 0 0 0 -0 0</pose>
        <scale>1 1 1</scale>
        <link name='link'>
          <pose frame=''>0 0 0 0 -0 0</pose>
          <velocity>0 0 0 0 -0 0</velocity>
          <acceleration>0 0 0 0 -0 0</acceleration>
          <wrench>0 0 0 0 -0 0</wrench>
        </link>
      </model>
      <model name='stop_light_post'>
        <pose frame=''>9.48189 5.98732 0 0 -0 0</pose>
        <scale>1 1 1</scale>
        <link name='center_light::link'>
          <pose frame=''>7.48189 6.02732 5.82 0 -0 0</pose>
          <velocity>0 0 0 0 -0 0</velocity>
          <acceleration>0 0 0 0 -0 0</acceleration>
          <wrench>0 0 0 0 -0 0</wrench>
        </link>
        <link name='link'>
          <pose frame=''>9.48189 5.98732 0 0 -0 0</pose>
          <velocity>0 0 0 0 -0 0</velocity>
          <acceleration>0 0 0 0 -0 0</acceleration>
          <wrench>0 0 0 0 -0 0</wrench>
        </link>
        <link name='right_light::link'>
          <pose frame=''>9.48189 5.93732 4 0 -0 0</pose>
          <velocity>0 0 0 0 -0 0</velocity>
          <acceleration>0 0 0 0 -0 0</acceleration>
          <wrench>0 0 0 0 -0 0</wrench>
        </link>
      </model>
      <model name='table_marble'>
        <pose frame=''>7.29977 7.98334 0.648 0 -0 0</pose>
        <scale>1 1 1</scale>
        <link name='link'>
          <pose frame=''>7.29977 7.98334 0.648 0 -0 0</pose>
          <velocity>0 0 0 0 -0 0</velocity>
          <acceleration>0 0 0 0 -0 0</acceleration>
          <wrench>0 0 0 0 -0 0</wrench>
        </link>
      </model>
      <model name='trisphere_cycle'>
        <pose frame=''>7.43698 -8.73706 0 0 -0 0</pose>
        <scale>1 1 1</scale>
        <link name='fork'>
          <pose frame=''>7.47842 -8.73706 0.385023 0 -0.174533 0</pose>
          <velocity>0 0 0 0 -0 0</velocity>
          <acceleration>0 0 0 0 -0 0</acceleration>
          <wrench>0 0 0 0 -0 0</wrench>
        </link>
        <link name='frame'>
          <pose frame=''>7.02842 -8.73706 0.385023 0 -0.522021 0</pose>
          <velocity>0 0 0 0 -0 0</velocity>
          <acceleration>0 0 0 0 -0 0</acceleration>
          <wrench>0 0 0 0 -0 0</wrench>
        </link>
        <link name='wheel_front'>
          <pose frame=''>7.51986 -8.73706 0.15 0 -0 0</pose>
          <velocity>0 0 0 0 -0 0</velocity>
          <acceleration>0 0 0 0 -0 0</acceleration>
          <wrench>0 0 0 0 -0 0</wrench>
        </link>
        <link name='wheel_rear_left'>
          <pose frame=''>6.61986 -8.21744 0.15 0 -0 0</pose>
          <velocity>0 0 0 0 -0 0</velocity>
          <acceleration>0 0 0 0 -0 0</acceleration>
          <wrench>0 0 0 0 -0 0</wrench>
        </link>
        <link name='wheel_rear_right'>
          <pose frame=''>6.61986 -9.25667 0.15 0 -0 0</pose>
          <velocity>0 0 0 0 -0 0</velocity>
          <acceleration>0 0 0 0 -0 0</acceleration>
          <wrench>0 0 0 0 -0 0</wrench>
        </link>
      </model>
      <model name='truss_bridge'>
        <pose frame=''>-5.71203 0.106755 0 0 -0 0</pose>
        <scale>1 1 1</scale>
        <link name='link'>
          <pose frame=''>-5.71203 0.106755 0 0 -0 0</pose>
          <velocity>0 0 0 0 -0 0</velocity>
          <acceleration>0 0 0 0 -0 0</acceleration>
          <wrench>0 0 0 0 -0 0</wrench>
        </link>
      </model>
      <model name='u_joint_part'>
        <pose frame=''>3.98792 -5.51985 0.07929 1.5707 -0 0</pose>
        <scale>1 1 1</scale>
        <link name='link'>
          <pose frame=''>3.98792 -5.51985 0.07929 1.5707 -0 0</pose>
          <velocity>0 0 0 0 -0 0</velocity>
          <acceleration>0 0 0 0 -0 0</acceleration>
          <wrench>0 0 0 0 -0 0</wrench>
        </link>
      </model>
      <model name='warehouse_robot'>
        <pose frame=''>6.49928 -5.99932 0 0 -0 0</pose>
        <scale>1 1 1</scale>
        <link name='link'>
          <pose frame=''>6.49928 -5.99932 0 0 -0 0</pose>
          <velocity>0 0 0 0 -0 0</velocity>
          <acceleration>0 0 0 0 -0 0</acceleration>
          <wrench>0 0 0 0 -0 0</wrench>
        </link>
      </model>
      <model name='water_tower'>
        <pose frame=''>4.73599 0.565297 0 0 -0 0</pose>
        <scale>1 1 1</scale>
        <link name='link'>
          <pose frame=''>4.73599 0.565297 0 0 -0 0</pose>
          <velocity>0 0 0 0 -0 0</velocity>
          <acceleration>0 0 0 0 -0 0</acceleration>
          <wrench>0 0 0 0 -0 0</wrench>
        </link>
      </model>
      <model name='wood_cube_10cm'>
        <pose frame=''>3.92861 -6.17078 0 0 -0 0</pose>
        <scale>1 1 1</scale>
        <link name='link'>
          <pose frame=''>3.92861 -6.17078 0.05 0 -0 0</pose>
          <velocity>0 0 0 0 -0 0</velocity>
          <acceleration>0 0 0 0 -0 0</acceleration>
          <wrench>0 0 0 0 -0 0</wrench>
        </link>
      </model>
      <model name='wooden_case_wooden_peg'>
        <pose frame=''>-1.50248 2.02358 0 0 -0 0</pose>
        <scale>1 1 1</scale>
        <link name='peg::link'>
          <pose frame=''>-1.13671 2.23958 0.05905 0 -0 0</pose>
          <velocity>0 0 0 0 -0 0</velocity>
          <acceleration>0 0 0 0 -0 0</acceleration>
          <wrench>0 0 0 0 -0 0</wrench>
        </link>
        <link name='wooden_case::base'>
          <pose frame=''>-1.50248 2.02358 0.024 0 -0 0</pose>
          <velocity>0 0 0 0 -0 0</velocity>
          <acceleration>0 0 0 0 -0 0</acceleration>
          <wrench>0 0 0 0 -0 0</wrench>
        </link>
        <link name='wooden_case::lid'>
          <pose frame=''>-1.2587 2.02358 0.009525 0 -0 0</pose>
          <velocity>0 0 0 0 -0 0</velocity>
          <acceleration>0 0 0 0 -0 0</acceleration>
          <wrench>0 0 0 0 -0 0</wrench>
        </link>
      </model>
      <model name='youbot'>
        <pose frame=''>-1.07999 -0.016942 0.09 0 -0 0</pose>
        <scale>1 1 1</scale>
        <link name='arm_link_0'>
          <pose frame=''>-0.93699 -0.016942 0.136 0 -0 0</pose>
          <velocity>0 0 0 0 -0 0</velocity>
          <acceleration>0 0 0 0 -0 0</acceleration>
          <wrench>0 0 0 0 -0 0</wrench>
        </link>
        <link name='arm_link_1'>
          <pose frame=''>-0.91299 -0.016942 0.232 0 -0 2.96706</pose>
          <velocity>0 0 0 0 -0 0</velocity>
          <acceleration>0 0 0 0 -0 0</acceleration>
          <wrench>0 0 0 0 -0 0</wrench>
        </link>
        <link name='arm_link_2'>
          <pose frame=''>-0.945489 -0.011212 0.251 0 -1.13446 2.96706</pose>
          <velocity>0 0 0 0 -0 0</velocity>
          <acceleration>0 0 0 0 -0 0</acceleration>
          <wrench>0 0 0 0 -0 0</wrench>
        </link>
        <link name='arm_link_3'>
          <pose frame=''>-0.807145 -0.035605 0.316506 -0 1.41372 2.96706</pose>
          <velocity>0 0 0 0 -0 0</velocity>
          <acceleration>0 0 0 0 -0 0</acceleration>
          <wrench>0 0 0 0 -0 0</wrench>
        </link>
        <link name='arm_link_4'>
          <pose frame=''>-0.938457 -0.012451 0.337624 0 -0.375246 2.96706</pose>
          <velocity>0 0 0 0 -0 0</velocity>
          <acceleration>0 0 0 0 -0 0</acceleration>
          <wrench>0 0 0 0 -0 0</wrench>
        </link>
        <link name='arm_link_5'>
          <pose frame=''>-0.889703 -0.021048 0.457846 -0.085052 0.365926 -0.408445</pose>
          <velocity>0 0 0 0 -0 0</velocity>
          <acceleration>0 0 0 0 -0 0</acceleration>
          <wrench>0 0 0 0 -0 0</wrench>
        </link>
        <link name='base_footprint'>
          <pose frame=''>-1.07999 -0.016942 0.09 0 -0 0</pose>
          <velocity>0 0 0 0 -0 0</velocity>
          <acceleration>0 0 0 0 -0 0</acceleration>
          <wrench>0 0 0 0 -0 0</wrench>
        </link>
        <link name='base_laser_front_link'>
          <pose frame=''>-0.77999 -0.016942 0.06 0 -0 0</pose>
          <velocity>0 0 0 0 -0 0</velocity>
          <acceleration>0 0 0 0 -0 0</acceleration>
          <wrench>0 0 0 0 -0 0</wrench>
        </link>
        <link name='base_link'>
          <pose frame=''>-1.07999 -0.016942 0.09 0 -0 0</pose>
          <velocity>0 0 0 0 -0 0</velocity>
          <acceleration>0 0 0 0 -0 0</acceleration>
          <wrench>0 0 0 0 -0 0</wrench>
        </link>
        <link name='caster_link_bl'>
          <pose frame=''>-1.30799 0.141058 0.056 0 -0 0</pose>
          <velocity>0 0 0 0 -0 0</velocity>
          <acceleration>0 0 0 0 -0 0</acceleration>
          <wrench>0 0 0 0 -0 0</wrench>
        </link>
        <link name='caster_link_br'>
          <pose frame=''>-1.30799 -0.174942 0.056 0 -0 0</pose>
          <velocity>0 0 0 0 -0 0</velocity>
          <acceleration>0 0 0 0 -0 0</acceleration>
          <wrench>0 0 0 0 -0 0</wrench>
        </link>
        <link name='caster_link_fl'>
          <pose frame=''>-0.85199 0.141058 0.056 0 -0 0</pose>
          <velocity>0 0 0 0 -0 0</velocity>
          <acceleration>0 0 0 0 -0 0</acceleration>
          <wrench>0 0 0 0 -0 0</wrench>
        </link>
        <link name='caster_link_fr'>
          <pose frame=''>-0.85199 -0.174942 0.056 0 -0 0</pose>
          <velocity>0 0 0 0 -0 0</velocity>
          <acceleration>0 0 0 0 -0 0</acceleration>
          <wrench>0 0 0 0 -0 0</wrench>
        </link>
        <link name='gripper_finger_link_l'>
          <pose frame=''>-0.86673 -0.018047 0.498579 0.085052 -0.365926 2.73315</pose>
          <velocity>0 0 0 0 -0 0</velocity>
          <acceleration>0 0 0 0 -0 0</acceleration>
          <wrench>0 0 0 0 -0 0</wrench>
        </link>
        <link name='gripper_finger_link_r'>
          <pose frame=''>-0.872615 -0.032871 0.499848 -0.085052 0.365926 -0.408445</pose>
          <velocity>0 0 0 0 -0 0</velocity>
          <acceleration>0 0 0 0 -0 0</acceleration>
          <wrench>0 0 0 0 -0 0</wrench>
        </link>
        <link name='gripper_palm_link'>
          <pose frame=''>-0.889703 -0.021048 0.457846 -0.085052 0.365926 -0.408445</pose>
          <velocity>0 0 0 0 -0 0</velocity>
          <acceleration>0 0 0 0 -0 0</acceleration>
          <wrench>0 0 0 0 -0 0</wrench>
        </link>
        <link name='plate_link'>
          <pose frame=''>-1.23899 -0.016942 0.136 0 -0 0</pose>
          <velocity>0 0 0 0 -0 0</velocity>
          <acceleration>0 0 0 0 -0 0</acceleration>
          <wrench>0 0 0 0 -0 0</wrench>
        </link>
        <link name='wheel_link_bl'>
          <pose frame=''>-1.30799 0.141058 0.056 0 -0 0</pose>
          <velocity>0 0 0 0 -0 0</velocity>
          <acceleration>0 0 0 0 -0 0</acceleration>
          <wrench>0 0 0 0 -0 0</wrench>
        </link>
        <link name='wheel_link_br'>
          <pose frame=''>-1.30799 -0.174942 0.056 0 -0 0</pose>
          <velocity>0 0 0 0 -0 0</velocity>
          <acceleration>0 0 0 0 -0 0</acceleration>
          <wrench>0 0 0 0 -0 0</wrench>
        </link>
        <link name='wheel_link_fl'>
          <pose frame=''>-0.85199 0.141058 0.056 0 -0 0</pose>
          <velocity>0 0 0 0 -0 0</velocity>
          <acceleration>0 0 0 0 -0 0</acceleration>
          <wrench>0 0 0 0 -0 0</wrench>
        </link>
        <link name='wheel_link_fr'>
          <pose frame=''>-0.85199 -0.174942 0.056 0 -0 0</pose>
          <velocity>0 0 0 0 -0 0</velocity>
          <acceleration>0 0 0 0 -0 0</acceleration>
          <wrench>0 0 0 0 -0 0</wrench>
        </link>
      </model>
      <light name='sun'>
        <pose frame=''>0 0 10 0 -0 0</pose>
      </light>
    </state>
    <gui fullscreen='0'>
      <camera name='user_camera'>
        <pose frame=''>6.16924 34.5593 35.3278 0 0.9898 -1.78795</pose>
        <view_controller>orbit</view_controller>
        <projection_type>perspective</projection_type>
      </camera>
    </gui>
    <model name='youbot'>
      <pose frame=''>-0.077267 -0.040168 0.09 0 -0 0</pose>
      <link name='base_footprint'>
        <pose frame=''>0 0 0 0 -0 0</pose>
        <inertial>
          <pose frame=''>0 0 -0.05 0 -0 0</pose>
          <inertia>
            <ixx>1</ixx>
            <ixy>0</ixy>
            <ixz>0</ixz>
            <iyy>1</iyy>
            <iyz>0</iyz>
            <izz>1</izz>
          </inertia>
          <mass>0.1</mass>
        </inertial>
        <collision name='base_footprint_geom'>
          <pose frame=''>0 0 -0.05 0 -0 0</pose>
          <geometry>
            <box>
              <size>0.001 0.001 0.001</size>
            </box>
          </geometry>
          <surface>
            <friction>
              <ode>
                <mu>0</mu>
                <mu2>0</mu2>
                <fdir1>0 0 0</fdir1>
                <slip1>0</slip1>
                <slip2>0</slip2>
              </ode>
              <torsional>
                <ode/>
              </torsional>
            </friction>
            <bounce>
              <restitution_coefficient>0</restitution_coefficient>
              <threshold>0</threshold>
            </bounce>
            <contact>
              <ode>
                <soft_cfm>0</soft_cfm>
                <soft_erp>0.2</soft_erp>
                <kp>1e+13</kp>
                <kd>1e+11</kd>
                <max_vel>-1</max_vel>
                <min_depth>0</min_depth>
              </ode>
            </contact>
          </surface>
          <laser_retro>0</laser_retro>
          <max_contacts>10</max_contacts>
        </collision>
        <visual name='base_footprint_geom_visual'>
          <pose frame=''>0 0 0 0 -0 0</pose>
          <geometry>
            <box>
              <size>0.001 0.001 0.001</size>
            </box>
          </geometry>
        </visual>
        <gravity>1</gravity>
        <self_collide>0</self_collide>
        <kinematic>0</kinematic>
      </link>
      <link name='base_link'>
        <pose frame=''>0 0 0 0 -0 0</pose>
        <inertial>
          <pose frame=''>0 0 0 0 -0 0</pose>
          <inertia>
            <ixx>5.65223</ixx>
            <ixy>-0.00972</ixy>
            <ixz>1.29399</ixz>
            <iyy>5.66947</iyy>
            <iyz>-0.00738</iyz>
            <izz>3.6832</izz>
          </inertia>
          <mass>22</mass>
        </inertial>
        <collision name='base_link_geom'>
          <pose frame=''>0 0 0 0 -0 0</pose>
          <geometry>
            <mesh>
              <uri>model://youbot/meshes/base/base_convex.stl</uri>
            </mesh>
          </geometry>
          <surface>
            <friction>
              <ode>
                <mu>0</mu>
                <mu2>0</mu2>
                <fdir1>0 0 0</fdir1>
                <slip1>0</slip1>
                <slip2>0</slip2>
              </ode>
              <torsional>
                <ode/>
              </torsional>
            </friction>
            <bounce>
              <restitution_coefficient>0</restitution_coefficient>
              <threshold>0</threshold>
            </bounce>
            <contact>
              <ode>
                <soft_cfm>0</soft_cfm>
                <soft_erp>0.2</soft_erp>
                <kp>1e+13</kp>
                <kd>1e+11</kd>
                <max_vel>-1</max_vel>
                <min_depth>0</min_depth>
              </ode>
            </contact>
          </surface>
          <laser_retro>0</laser_retro>
          <max_contacts>10</max_contacts>
        </collision>
        <visual name='base_link_geom_visual'>
          <pose frame=''>0 0 0 0 -0 0</pose>
          <geometry>
            <mesh>
              <uri>model://youbot/meshes/base/base.dae</uri>
            </mesh>
          </geometry>
        </visual>
        <gravity>1</gravity>
        <self_collide>0</self_collide>
        <kinematic>0</kinematic>
      </link>
      <link name='arm_link_0'>
        <pose frame=''>0.143 0 0.046 0 -0 0</pose>
        <inertial>
          <pose frame=''>0 0 0 0 -0 0</pose>
          <inertia>
            <ixx>0.01</ixx>
            <ixy>0</ixy>
            <ixz>0</ixz>
            <iyy>0.01</iyy>
            <iyz>0</iyz>
            <izz>0.01</izz>
          </inertia>
          <mass>0.845</mass>
        </inertial>
        <collision name='arm_link_0_geom'>
          <pose frame=''>0 0 0 0 -0 0</pose>
          <geometry>
            <mesh>
              <uri>model://youbot/meshes/arm/arm0_convex.stl</uri>
            </mesh>
          </geometry>
          <surface>
            <friction>
              <ode>
                <mu>0</mu>
                <mu2>0</mu2>
                <fdir1>0 0 0</fdir1>
                <slip1>0</slip1>
                <slip2>0</slip2>
              </ode>
              <torsional>
                <ode/>
              </torsional>
            </friction>
            <bounce>
              <restitution_coefficient>0</restitution_coefficient>
              <threshold>0</threshold>
            </bounce>
            <contact>
              <ode>
                <soft_cfm>0</soft_cfm>
                <soft_erp>0.2</soft_erp>
                <kp>1e+13</kp>
                <kd>1e+11</kd>
                <max_vel>-1</max_vel>
                <min_depth>0</min_depth>
              </ode>
            </contact>
          </surface>
          <laser_retro>0</laser_retro>
          <max_contacts>10</max_contacts>
        </collision>
        <visual name='arm_link_0_geom_visual'>
          <pose frame=''>0 0 0 0 -0 0</pose>
          <geometry>
            <mesh>
              <uri>model://youbot/meshes/arm/arm0.dae</uri>
            </mesh>
          </geometry>
          <material>
            <script>
              <uri>model://youbot/materials/scripts/youbot.material</uri>
              <name>youbot/DarkGrey</name>
            </script>
          </material>
        </visual>
        <gravity>1</gravity>
        <self_collide>0</self_collide>
        <kinematic>0</kinematic>
      </link>
      <link name='arm_link_1'>
        <pose frame=''>0.167 0 0.142 0 -0 2.96706</pose>
        <inertial>
          <pose frame=''>0.01489 0.00213 0.00213 0 -0 0</pose>
          <inertia>
            <ixx>0.003863</ixx>
            <ixy>-0.000979</ixy>
            <ixz>0</ixz>
            <iyy>0.006196</iyy>
            <iyz>0</iyz>
            <izz>0.006369</izz>
          </inertia>
          <mass>2.412</mass>
        </inertial>
        <collision name='arm_link_1_geom'>
          <pose frame=''>0 0 0 0 -0 0</pose>
          <geometry>
            <mesh>
              <uri>model://youbot/meshes/arm/arm1_convex.stl</uri>
            </mesh>
          </geometry>
          <surface>
            <friction>
              <ode>
                <mu>0</mu>
                <mu2>0</mu2>
                <fdir1>0 0 0</fdir1>
                <slip1>0</slip1>
                <slip2>0</slip2>
              </ode>
              <torsional>
                <ode/>
              </torsional>
            </friction>
            <bounce>
              <restitution_coefficient>0</restitution_coefficient>
              <threshold>0</threshold>
            </bounce>
            <contact>
              <ode>
                <soft_cfm>0</soft_cfm>
                <soft_erp>0.2</soft_erp>
                <kp>1e+13</kp>
                <kd>1e+11</kd>
                <max_vel>-1</max_vel>
                <min_depth>0</min_depth>
              </ode>
            </contact>
          </surface>
          <laser_retro>0</laser_retro>
          <max_contacts>10</max_contacts>
        </collision>
        <visual name='arm_link_1_geom_visual'>
          <pose frame=''>0 0 0 0 -0 0</pose>
          <geometry>
            <mesh>
              <uri>model://youbot/meshes/arm/arm1.dae</uri>
            </mesh>
          </geometry>
        </visual>
        <gravity>1</gravity>
        <self_collide>0</self_collide>
        <kinematic>0</kinematic>
      </link>
      <link name='arm_link_2'>
        <pose frame=''>0.134501 0.00573 0.161 0 -1.13446 2.96706</pose>
        <inertial>
          <pose frame=''>0.10453 0.0017 -0.00297 0 -0 0</pose>
          <inertia>
            <ixx>0.000823</ixx>
            <ixy>0</ixy>
            <ixz>-0</ixz>
            <iyy>0.004447</iyy>
            <iyz>0</iyz>
            <izz>0.004439</izz>
          </inertia>
          <mass>1.155</mass>
        </inertial>
        <collision name='arm_link_2_geom'>
          <pose frame=''>0 -0.032 0.078 0 -0 0</pose>
          <geometry>
            <mesh>
              <uri>model://youbot/meshes/arm/arm2_convex.stl</uri>
            </mesh>
          </geometry>
          <surface>
            <friction>
              <ode>
                <mu>0</mu>
                <mu2>0</mu2>
                <fdir1>0 0 0</fdir1>
                <slip1>0</slip1>
                <slip2>0</slip2>
              </ode>
              <torsional>
                <ode/>
              </torsional>
            </friction>
            <bounce>
              <restitution_coefficient>0</restitution_coefficient>
              <threshold>0</threshold>
            </bounce>
            <contact>
              <ode>
                <soft_cfm>0</soft_cfm>
                <soft_erp>0.2</soft_erp>
                <kp>1e+13</kp>
                <kd>1e+11</kd>
                <max_vel>-1</max_vel>
                <min_depth>0</min_depth>
              </ode>
            </contact>
          </surface>
          <laser_retro>0</laser_retro>
          <max_contacts>10</max_contacts>
        </collision>
        <visual name='arm_link_2_geom_visual'>
          <pose frame=''>0 -0.032 0.078 0 -0 0</pose>
          <geometry>
            <mesh>
              <uri>model://youbot/meshes/arm/arm2.dae</uri>
            </mesh>
          </geometry>
        </visual>
        <gravity>1</gravity>
        <self_collide>0</self_collide>
        <kinematic>0</kinematic>
      </link>
      <link name='arm_link_3'>
        <pose frame=''>0.272845 -0.018663 0.226506 -0 1.41372 2.96706</pose>
        <inertial>
          <pose frame=''>0.0001 0.0967 0.02107 0 -0 0</pose>
          <inertia>
            <ixx>0.002459</ixx>
            <ixy>0</ixy>
            <ixz>0</ixz>
            <iyy>0.002571</iyy>
            <iyz>-0</iyz>
            <izz>0.000535</izz>
          </inertia>
          <mass>0.934</mass>
        </inertial>
        <collision name='arm_link_3_geom'>
          <pose frame=''>0 0.028 0.079 0 -0 0</pose>
          <geometry>
            <mesh>
              <uri>model://youbot/meshes/arm/arm3_convex.stl</uri>
            </mesh>
          </geometry>
          <surface>
            <friction>
              <ode>
                <mu>0</mu>
                <mu2>0</mu2>
                <fdir1>0 0 0</fdir1>
                <slip1>0</slip1>
                <slip2>0</slip2>
              </ode>
              <torsional>
                <ode/>
              </torsional>
            </friction>
            <bounce>
              <restitution_coefficient>0</restitution_coefficient>
              <threshold>0</threshold>
            </bounce>
            <contact>
              <ode>
                <soft_cfm>0</soft_cfm>
                <soft_erp>0.2</soft_erp>
                <kp>1e+13</kp>
                <kd>1e+11</kd>
                <max_vel>-1</max_vel>
                <min_depth>0</min_depth>
              </ode>
            </contact>
          </surface>
          <laser_retro>0</laser_retro>
          <max_contacts>10</max_contacts>
        </collision>
        <visual name='arm_link_3_geom_visual'>
          <pose frame=''>0 0.028 0.079 0 -0 0</pose>
          <geometry>
            <mesh>
              <uri>model://youbot/meshes/arm/arm3.dae</uri>
            </mesh>
          </geometry>
        </visual>
        <gravity>1</gravity>
        <self_collide>0</self_collide>
        <kinematic>0</kinematic>
      </link>
      <link name='arm_link_4'>
        <pose frame=''>0.141533 0.004491 0.247624 0 -0.375246 2.96706</pose>
        <inertial>
          <pose frame=''>0.00011 0.05103 -0.02319 0 -0 0</pose>
          <inertia>
            <ixx>0.000869</ixx>
            <ixy>0</ixy>
            <ixz>-0</ixz>
            <iyy>0.001173</iyy>
            <iyz>-0.000231</iyz>
            <izz>0.001091</izz>
          </inertia>
          <mass>0.877</mass>
        </inertial>
        <collision name='arm_link_4_geom'>
          <pose frame=''>0 -0.01 0.029 0 -0 0</pose>
          <geometry>
            <mesh>
              <uri>model://youbot/meshes/arm/arm4_convex.stl</uri>
            </mesh>
          </geometry>
          <surface>
            <friction>
              <ode>
                <mu>0</mu>
                <mu2>0</mu2>
                <fdir1>0 0 0</fdir1>
                <slip1>0</slip1>
                <slip2>0</slip2>
              </ode>
              <torsional>
                <ode/>
              </torsional>
            </friction>
            <bounce>
              <restitution_coefficient>0</restitution_coefficient>
              <threshold>0</threshold>
            </bounce>
            <contact>
              <ode>
                <soft_cfm>0</soft_cfm>
                <soft_erp>0.2</soft_erp>
                <kp>1e+13</kp>
                <kd>1e+11</kd>
                <max_vel>-1</max_vel>
                <min_depth>0</min_depth>
              </ode>
            </contact>
          </surface>
          <laser_retro>0</laser_retro>
          <max_contacts>10</max_contacts>
        </collision>
        <visual name='arm_link_4_geom_visual'>
          <pose frame=''>0 -0.01 0.029 0 -0 0</pose>
          <geometry>
            <mesh>
              <uri>model://youbot/meshes/arm/arm4.dae</uri>
            </mesh>
          </geometry>
        </visual>
        <gravity>1</gravity>
        <self_collide>0</self_collide>
        <kinematic>0</kinematic>
      </link>
      <link name='arm_link_5'>
        <pose frame=''>0.190287 -0.004106 0.367846 -0.085052 0.365926 -0.408445</pose>
        <inertial>
          <pose frame=''>0 0.00115 -0.01683 0 -0 0</pose>
          <inertia>
            <ixx>0.00028</ixx>
            <ixy>0</ixy>
            <ixz>0</ixz>
            <iyy>0.000339</iyy>
            <iyz>0</iyz>
            <izz>0.000119</izz>
          </inertia>
          <mass>0.251</mass>
        </inertial>
        <collision name='arm_link_5_geom'>
          <pose frame=''>0.003 0 -0.034 0 -0 0</pose>
          <geometry>
            <mesh>
              <uri>model://youbot/meshes/arm/arm5_convex.stl</uri>
            </mesh>
          </geometry>
          <surface>
            <bounce>
              <restitution_coefficient>0</restitution_coefficient>
              <threshold>0</threshold>
            </bounce>
            <contact>
              <ode>
                <soft_cfm>0</soft_cfm>
                <soft_erp>0.2</soft_erp>
                <kp>1e+13</kp>
                <kd>1e+11</kd>
                <max_vel>-1</max_vel>
                <min_depth>0</min_depth>
              </ode>
            </contact>
            <friction>
              <torsional>
                <ode/>
              </torsional>
              <ode/>
            </friction>
          </surface>
          <laser_retro>0</laser_retro>
          <max_contacts>10</max_contacts>
        </collision>
        <visual name='arm_link_5_geom_visual'>
          <pose frame=''>0.003 0 -0.034 0 -0 0</pose>
          <geometry>
            <mesh>
              <uri>model://youbot/meshes/arm/arm5.dae</uri>
            </mesh>
          </geometry>
        </visual>
        <gravity>1</gravity>
        <self_collide>0</self_collide>
        <kinematic>0</kinematic>
      </link>
      <link name='gripper_palm_link'>
        <pose frame=''>0.190287 -0.004106 0.367846 -0.085052 0.365926 -0.408445</pose>
        <inertial>
          <pose frame=''>0 0 0 0 -0 0</pose>
          <inertia>
            <ixx>0.01</ixx>
            <ixy>0</ixy>
            <ixz>0</ixz>
            <iyy>0.01</iyy>
            <iyz>0</iyz>
            <izz>0.01</izz>
          </inertia>
          <mass>0.1</mass>
        </inertial>
        <collision name='gripper_palm_link_geom'>
          <pose frame=''>0 0 0 0 -0 0</pose>
          <geometry>
            <mesh>
              <uri>model://youbot/meshes/gripper/palm_convex.stl</uri>
            </mesh>
          </geometry>
          <surface>
            <friction>
              <ode>
                <mu>0</mu>
                <mu2>0</mu2>
                <fdir1>0 0 0</fdir1>
                <slip1>0</slip1>
                <slip2>0</slip2>
              </ode>
              <torsional>
                <ode/>
              </torsional>
            </friction>
            <bounce>
              <restitution_coefficient>0</restitution_coefficient>
              <threshold>0</threshold>
            </bounce>
            <contact>
              <ode>
                <soft_cfm>0</soft_cfm>
                <soft_erp>0.2</soft_erp>
                <kp>1e+13</kp>
                <kd>1e+11</kd>
                <max_vel>-1</max_vel>
                <min_depth>0</min_depth>
              </ode>
            </contact>
          </surface>
          <laser_retro>0</laser_retro>
          <max_contacts>10</max_contacts>
        </collision>
        <visual name='gripper_palm_link_geom_visual'>
          <pose frame=''>0 0 0 0 -0 0</pose>
          <geometry>
            <mesh>
              <uri>model://youbot/meshes/gripper/palm.stl</uri>
            </mesh>
          </geometry>
          <material>
            <script>
              <uri>file://media/materials/scripts/gazebo.material</uri>
              <name>Gazebo/Black</name>
            </script>
          </material>
        </visual>
        <gravity>1</gravity>
        <self_collide>1</self_collide>
        <kinematic>0</kinematic>
      </link>
      <link name='gripper_finger_link_l'>
        <pose frame=''>0.21326 -0.001105 0.408579 0.085052 -0.365926 2.73315</pose>
        <inertial>
          <pose frame=''>0 -0.001 0 0 -0 0</pose>
          <inertia>
            <ixx>0.01</ixx>
            <ixy>0</ixy>
            <ixz>0</ixz>
            <iyy>0.01</iyy>
            <iyz>0</iyz>
            <izz>0.01</izz>
          </inertia>
          <mass>0.01</mass>
        </inertial>
        <collision name='gripper_finger_link_l_geom'>
          <pose frame=''>0 0 0 0 -0 0</pose>
          <geometry>
            <mesh>
              <uri>model://youbot/meshes/gripper/finger_convex.stl</uri>
            </mesh>
          </geometry>
          <surface>
            <bounce>
              <restitution_coefficient>0</restitution_coefficient>
              <threshold>0</threshold>
            </bounce>
            <contact>
              <ode>
                <soft_cfm>0</soft_cfm>
                <soft_erp>0.2</soft_erp>
                <kp>1e+13</kp>
                <kd>1e+11</kd>
                <max_vel>-1</max_vel>
                <min_depth>0</min_depth>
              </ode>
            </contact>
            <friction>
              <torsional>
                <ode/>
              </torsional>
              <ode/>
            </friction>
          </surface>
          <laser_retro>0</laser_retro>
          <max_contacts>10</max_contacts>
        </collision>
        <visual name='gripper_finger_link_l_geom_visual'>
          <pose frame=''>0 0 0 0 -0 0</pose>
          <geometry>
            <mesh>
              <uri>model://youbot/meshes/gripper/finger.stl</uri>
            </mesh>
          </geometry>
        </visual>
        <gravity>1</gravity>
        <self_collide>0</self_collide>
        <kinematic>0</kinematic>
      </link>
      <link name='gripper_finger_link_r'>
        <pose frame=''>0.207375 -0.015929 0.409848 -0.085052 0.365926 -0.408445</pose>
        <inertial>
          <pose frame=''>0 -0.001 0 0 -0 0</pose>
          <inertia>
            <ixx>0.01</ixx>
            <ixy>0</ixy>
            <ixz>0</ixz>
            <iyy>0.01</iyy>
            <iyz>0</iyz>
            <izz>0.01</izz>
          </inertia>
          <mass>0.01</mass>
        </inertial>
        <collision name='gripper_finger_link_r_geom'>
          <pose frame=''>0 0 0 0 -0 0</pose>
          <geometry>
            <mesh>
              <uri>model://youbot/meshes/gripper/finger_convex.stl</uri>
            </mesh>
          </geometry>
          <surface>
            <bounce>
              <restitution_coefficient>0</restitution_coefficient>
              <threshold>0</threshold>
            </bounce>
            <contact>
              <ode>
                <soft_cfm>0</soft_cfm>
                <soft_erp>0.2</soft_erp>
                <kp>1e+13</kp>
                <kd>1e+11</kd>
                <max_vel>-1</max_vel>
                <min_depth>0</min_depth>
              </ode>
            </contact>
            <friction>
              <torsional>
                <ode/>
              </torsional>
              <ode/>
            </friction>
          </surface>
          <laser_retro>0</laser_retro>
          <max_contacts>10</max_contacts>
        </collision>
        <visual name='gripper_finger_link_r_geom_visual'>
          <pose frame=''>0 0 0 0 -0 0</pose>
          <geometry>
            <mesh>
              <uri>model://youbot/meshes/gripper/finger.stl</uri>
            </mesh>
          </geometry>
        </visual>
        <gravity>1</gravity>
        <self_collide>0</self_collide>
        <kinematic>0</kinematic>
      </link>
      <link name='base_laser_front_link'>
        <pose frame=''>0.3 0 -0.03 0 -0 0</pose>
        <inertial>
          <pose frame=''>0 0 0 0 -0 0</pose>
          <inertia>
            <ixx>0.1</ixx>
            <ixy>0</ixy>
            <ixz>0</ixz>
            <iyy>0.1</iyy>
            <iyz>0</iyz>
            <izz>0.1</izz>
          </inertia>
          <mass>0.16</mass>
        </inertial>
        <collision name='base_laser_front_link_geom'>
          <pose frame=''>0 0 0 0 -0 0</pose>
          <geometry>
            <mesh>
              <uri>model://hokuyo/meshes/hokuyo_convex.stl</uri>
            </mesh>
          </geometry>
          <surface>
            <bounce>
              <restitution_coefficient>0</restitution_coefficient>
              <threshold>0</threshold>
            </bounce>
            <contact>
              <ode>
                <soft_cfm>0</soft_cfm>
                <soft_erp>0.2</soft_erp>
                <kp>1e+13</kp>
                <kd>1e+11</kd>
                <max_vel>-1</max_vel>
                <min_depth>0</min_depth>
              </ode>
            </contact>
            <friction>
              <torsional>
                <ode/>
              </torsional>
              <ode/>
            </friction>
          </surface>
          <laser_retro>0</laser_retro>
          <max_contacts>10</max_contacts>
        </collision>
        <visual name='base_laser_front_link_geom_visual'>
          <pose frame=''>0 0 0 0 -0 0</pose>
          <geometry>
            <mesh>
              <uri>model://hokuyo/meshes/hokuyo.dae</uri>
            </mesh>
          </geometry>
        </visual>
        <sensor name='base_laser_front' type='ray'>
          <pose frame=''>0 0 0 0 -0 0</pose>
          <ray>
            <scan>
              <horizontal>
                <samples>640</samples>
                <resolution>1</resolution>
                <min_angle>-1.57</min_angle>
                <max_angle>1.57</max_angle>
              </horizontal>
              <vertical>
                <samples>1</samples>
                <min_angle>0</min_angle>
                <max_angle>0</max_angle>
              </vertical>
            </scan>
            <range>
              <min>0.05</min>
              <max>5.6</max>
              <resolution>0.36</resolution>
            </range>
          </ray>
          <always_on>0</always_on>
          <update_rate>10</update_rate>
          <visualize>0</visualize>
        </sensor>
        <gravity>1</gravity>
        <self_collide>0</self_collide>
        <kinematic>0</kinematic>
      </link>
      <link name='caster_link_bl'>
        <pose frame=''>-0.228 0.158 -0.034 0 -0 0</pose>
        <inertial>
          <pose frame=''>0 0 0 0 -0 0</pose>
          <inertia>
            <ixx>0.012412</ixx>
            <ixy>-0.000712</ixy>
            <ixz>0.000503</ixz>
            <iyy>0.015218</iyy>
            <iyz>-4e-06</iyz>
            <izz>0.011764</izz>
          </inertia>
          <mass>0.1</mass>
        </inertial>
        <gravity>1</gravity>
        <self_collide>0</self_collide>
        <kinematic>0</kinematic>
      </link>
      <link name='wheel_link_bl'>
        <pose frame=''>-0.228 0.158 -0.034 0 -0 0</pose>
        <inertial>
          <pose frame=''>0 0 0 0 -0 0</pose>
          <inertia>
            <ixx>0.012412</ixx>
            <ixy>-0.000712</ixy>
            <ixz>0.000503</ixz>
            <iyy>0.015218</iyy>
            <iyz>-4e-06</iyz>
            <izz>0.011764</izz>
          </inertia>
          <mass>0.4</mass>
        </inertial>
        <collision name='wheel_link_bl_geom'>
          <pose frame=''>0 0 0 1.5708 -0 0</pose>
          <geometry>
            <cylinder>
              <radius>0.05</radius>
              <length>0.005</length>
            </cylinder>
          </geometry>
          <surface>
            <bounce>
              <restitution_coefficient>0</restitution_coefficient>
              <threshold>0</threshold>
            </bounce>
            <contact>
              <ode>
                <soft_cfm>0</soft_cfm>
                <soft_erp>0.2</soft_erp>
                <kp>1e+13</kp>
                <kd>1e+11</kd>
                <max_vel>-1</max_vel>
                <min_depth>0</min_depth>
              </ode>
            </contact>
            <friction>
              <torsional>
                <ode/>
              </torsional>
              <ode/>
            </friction>
          </surface>
          <laser_retro>0</laser_retro>
          <max_contacts>10</max_contacts>
        </collision>
        <visual name='wheel_link_bl_geom_visual'>
          <pose frame=''>0 0 0 0 -0 0</pose>
          <geometry>
            <mesh>
              <uri>model://youbot/meshes/base/back-left_wheel.dae</uri>
            </mesh>
          </geometry>
          <material>
            <script>
              <uri>model://youbot/materials/scripts/youbot.material</uri>
              <name>youbot/Orange</name>
            </script>
          </material>
        </visual>
        <gravity>1</gravity>
        <self_collide>0</self_collide>
        <kinematic>0</kinematic>
      </link>
      <link name='caster_link_br'>
        <pose frame=''>-0.228 -0.158 -0.034 0 -0 0</pose>
        <inertial>
          <pose frame=''>0 0 0 0 -0 0</pose>
          <inertia>
            <ixx>0.012412</ixx>
            <ixy>-0.000712</ixy>
            <ixz>0.000503</ixz>
            <iyy>0.015218</iyy>
            <iyz>-4e-06</iyz>
            <izz>0.011764</izz>
          </inertia>
          <mass>0.1</mass>
        </inertial>
        <gravity>1</gravity>
        <self_collide>0</self_collide>
        <kinematic>0</kinematic>
      </link>
      <link name='wheel_link_br'>
        <pose frame=''>-0.228 -0.158 -0.034 0 -0 0</pose>
        <inertial>
          <pose frame=''>0 0 0 0 -0 0</pose>
          <inertia>
            <ixx>0.012412</ixx>
            <ixy>-0.000712</ixy>
            <ixz>0.000503</ixz>
            <iyy>0.015218</iyy>
            <iyz>-4e-06</iyz>
            <izz>0.011764</izz>
          </inertia>
          <mass>0.4</mass>
        </inertial>
        <collision name='wheel_link_br_geom'>
          <pose frame=''>0 0 0 1.5708 -0 0</pose>
          <geometry>
            <cylinder>
              <radius>0.05</radius>
              <length>0.005</length>
            </cylinder>
          </geometry>
          <surface>
            <bounce>
              <restitution_coefficient>0</restitution_coefficient>
              <threshold>0</threshold>
            </bounce>
            <contact>
              <ode>
                <soft_cfm>0</soft_cfm>
                <soft_erp>0.2</soft_erp>
                <kp>1e+13</kp>
                <kd>1e+11</kd>
                <max_vel>-1</max_vel>
                <min_depth>0</min_depth>
              </ode>
            </contact>
            <friction>
              <torsional>
                <ode/>
              </torsional>
              <ode/>
            </friction>
          </surface>
          <laser_retro>0</laser_retro>
          <max_contacts>10</max_contacts>
        </collision>
        <visual name='wheel_link_br_geom_visual'>
          <pose frame=''>0 0 0 0 -0 0</pose>
          <geometry>
            <mesh>
              <uri>model://youbot/meshes/base/back-right_wheel.dae</uri>
            </mesh>
          </geometry>
          <material>
            <script>
              <uri>model://youbot/materials/scripts/youbot.material</uri>
              <name>youbot/Orange</name>
            </script>
          </material>
        </visual>
        <gravity>1</gravity>
        <self_collide>0</self_collide>
        <kinematic>0</kinematic>
      </link>
      <link name='caster_link_fl'>
        <pose frame=''>0.228 0.158 -0.034 0 -0 0</pose>
        <inertial>
          <pose frame=''>0 0 0 0 -0 0</pose>
          <inertia>
            <ixx>0.012412</ixx>
            <ixy>-0.000712</ixy>
            <ixz>0.000503</ixz>
            <iyy>0.015218</iyy>
            <iyz>-4e-06</iyz>
            <izz>0.011764</izz>
          </inertia>
          <mass>0.1</mass>
        </inertial>
        <gravity>1</gravity>
        <self_collide>0</self_collide>
        <kinematic>0</kinematic>
      </link>
      <link name='wheel_link_fl'>
        <pose frame=''>0.228 0.158 -0.034 0 -0 0</pose>
        <inertial>
          <pose frame=''>0 0 0 0 -0 0</pose>
          <inertia>
            <ixx>0.012412</ixx>
            <ixy>-0.000712</ixy>
            <ixz>0.000503</ixz>
            <iyy>0.015218</iyy>
            <iyz>-4e-06</iyz>
            <izz>0.011764</izz>
          </inertia>
          <mass>0.4</mass>
        </inertial>
        <collision name='wheel_link_fl_geom'>
          <pose frame=''>0 0 0 1.5708 -0 0</pose>
          <geometry>
            <cylinder>
              <radius>0.05</radius>
              <length>0.005</length>
            </cylinder>
          </geometry>
          <surface>
            <bounce>
              <restitution_coefficient>0</restitution_coefficient>
              <threshold>0</threshold>
            </bounce>
            <contact>
              <ode>
                <soft_cfm>0</soft_cfm>
                <soft_erp>0.2</soft_erp>
                <kp>1e+13</kp>
                <kd>1e+11</kd>
                <max_vel>-1</max_vel>
                <min_depth>0</min_depth>
              </ode>
            </contact>
            <friction>
              <torsional>
                <ode/>
              </torsional>
              <ode/>
            </friction>
          </surface>
          <laser_retro>0</laser_retro>
          <max_contacts>10</max_contacts>
        </collision>
        <visual name='wheel_link_fl_geom_visual'>
          <pose frame=''>0 0 0 0 -0 0</pose>
          <geometry>
            <mesh>
              <uri>model://youbot/meshes/base/front-left_wheel.dae</uri>
            </mesh>
          </geometry>
          <material>
            <script>
              <uri>model://youbot/materials/scripts/youbot.material</uri>
              <name>youbot/Orange</name>
            </script>
          </material>
        </visual>
        <gravity>1</gravity>
        <self_collide>0</self_collide>
        <kinematic>0</kinematic>
      </link>
      <link name='caster_link_fr'>
        <pose frame=''>0.228 -0.158 -0.034 0 -0 0</pose>
        <inertial>
          <pose frame=''>0 0 0 0 -0 0</pose>
          <inertia>
            <ixx>0.012412</ixx>
            <ixy>-0.000712</ixy>
            <ixz>0.000503</ixz>
            <iyy>0.015218</iyy>
            <iyz>-4e-06</iyz>
            <izz>0.011764</izz>
          </inertia>
          <mass>0.1</mass>
        </inertial>
        <gravity>1</gravity>
        <self_collide>0</self_collide>
        <kinematic>0</kinematic>
      </link>
      <link name='wheel_link_fr'>
        <pose frame=''>0.228 -0.158 -0.034 0 -0 0</pose>
        <inertial>
          <pose frame=''>0 0 0 0 -0 0</pose>
          <inertia>
            <ixx>0.012412</ixx>
            <ixy>-0.000712</ixy>
            <ixz>0.000503</ixz>
            <iyy>0.015218</iyy>
            <iyz>-4e-06</iyz>
            <izz>0.011764</izz>
          </inertia>
          <mass>0.4</mass>
        </inertial>
        <collision name='wheel_link_fr_geom'>
          <pose frame=''>0 0 0 1.5708 -0 0</pose>
          <geometry>
            <cylinder>
              <radius>0.05</radius>
              <length>0.005</length>
            </cylinder>
          </geometry>
          <surface>
            <bounce>
              <restitution_coefficient>0</restitution_coefficient>
              <threshold>0</threshold>
            </bounce>
            <contact>
              <ode>
                <soft_cfm>0</soft_cfm>
                <soft_erp>0.2</soft_erp>
                <kp>1e+13</kp>
                <kd>1e+11</kd>
                <max_vel>-1</max_vel>
                <min_depth>0</min_depth>
              </ode>
            </contact>
            <friction>
              <torsional>
                <ode/>
              </torsional>
              <ode/>
            </friction>
          </surface>
          <laser_retro>0</laser_retro>
          <max_contacts>10</max_contacts>
        </collision>
        <visual name='wheel_link_fr_geom_visual'>
          <pose frame=''>0 0 0 0 -0 0</pose>
          <geometry>
            <mesh>
              <uri>model://youbot/meshes/base/front-right_wheel.dae</uri>
            </mesh>
          </geometry>
          <material>
            <script>
              <uri>model://youbot/materials/scripts/youbot.material</uri>
              <name>youbot/Orange</name>
            </script>
          </material>
        </visual>
        <gravity>1</gravity>
        <self_collide>0</self_collide>
        <kinematic>0</kinematic>
      </link>
      <link name='plate_link'>
        <pose frame=''>-0.159 0 0.046 0 -0 0</pose>
        <inertial>
          <pose frame=''>0 0 0 0 -0 0</pose>
          <inertia>
            <ixx>0.01</ixx>
            <ixy>0</ixy>
            <ixz>0</ixz>
            <iyy>0.01</iyy>
            <iyz>0</iyz>
            <izz>0.01</izz>
          </inertia>
          <mass>1</mass>
        </inertial>
        <collision name='plate_link_geom'>
          <pose frame=''>0 0 0 0 -0 0</pose>
          <geometry>
            <mesh>
              <uri>model://youbot/meshes/plate/plate_convex.stl</uri>
            </mesh>
          </geometry>
          <surface>
            <bounce>
              <restitution_coefficient>0</restitution_coefficient>
              <threshold>0</threshold>
            </bounce>
            <contact>
              <ode>
                <soft_cfm>0</soft_cfm>
                <soft_erp>0.2</soft_erp>
                <kp>1e+13</kp>
                <kd>1e+11</kd>
                <max_vel>-1</max_vel>
                <min_depth>0</min_depth>
              </ode>
            </contact>
            <friction>
              <torsional>
                <ode/>
              </torsional>
              <ode/>
            </friction>
          </surface>
          <laser_retro>0</laser_retro>
          <max_contacts>10</max_contacts>
        </collision>
        <visual name='plate_link_geom_visual'>
          <pose frame=''>0 0 0 0 -0 0</pose>
          <geometry>
            <mesh>
              <uri>model://youbot/meshes/plate/plate.dae</uri>
            </mesh>
          </geometry>
        </visual>
        <gravity>1</gravity>
        <self_collide>0</self_collide>
        <kinematic>0</kinematic>
      </link>
      <joint name='base_footprint_joint' type='revolute'>
        <pose frame=''>0 0 0 0 -0 0</pose>
        <parent>base_footprint</parent>
        <child>base_link</child>
        <axis>
          <dynamics>
            <damping>0</damping>
            <friction>0</friction>
            <spring_reference>0</spring_reference>
            <spring_stiffness>0</spring_stiffness>
          </dynamics>
          <limit>
            <lower>0</lower>
            <upper>0</upper>
            <effort>0</effort>
            <velocity>0</velocity>
          </limit>
          <xyz>0 0 1</xyz>
          <use_parent_model_frame>1</use_parent_model_frame>
        </axis>
      </joint>
      <joint name='arm_joint_0' type='revolute'>
        <pose frame=''>0 0 0 0 -0 0</pose>
        <parent>base_link</parent>
        <child>arm_link_0</child>
        <axis>
          <dynamics>
            <damping>0</damping>
            <friction>0</friction>
            <spring_reference>0</spring_reference>
            <spring_stiffness>0</spring_stiffness>
          </dynamics>
          <limit>
            <lower>0</lower>
            <upper>0</upper>
            <effort>0</effort>
            <velocity>0</velocity>
          </limit>
          <xyz>0 0 1</xyz>
          <use_parent_model_frame>1</use_parent_model_frame>
        </axis>
      </joint>
      <joint name='arm_joint_1' type='revolute'>
        <pose frame=''>0 0 0 0 -0 0</pose>
        <parent>arm_link_0</parent>
        <child>arm_link_1</child>
        <axis>
          <dynamics>
            <damping>1</damping>
            <friction>0</friction>
            <spring_reference>0</spring_reference>
            <spring_stiffness>0</spring_stiffness>
          </dynamics>
          <limit>
            <lower>0</lower>
            <upper>5.89921</upper>
            <effort>9.5</effort>
          </limit>
          <xyz>0 0 -1</xyz>
          <use_parent_model_frame>1</use_parent_model_frame>
        </axis>
      </joint>
      <joint name='arm_joint_2' type='revolute'>
        <pose frame=''>0 0 0 0 -0 0</pose>
        <parent>arm_link_1</parent>
        <child>arm_link_2</child>
        <axis>
          <dynamics>
            <damping>1</damping>
            <friction>0</friction>
            <spring_reference>0</spring_reference>
            <spring_stiffness>0</spring_stiffness>
          </dynamics>
          <limit>
            <lower>0</lower>
            <upper>2.70526</upper>
            <effort>9.5</effort>
            <velocity>-1</velocity>
          </limit>
          <xyz>-0.173648 -0.984808 0</xyz>
          <use_parent_model_frame>1</use_parent_model_frame>
        </axis>
      </joint>
      <joint name='arm_joint_3' type='revolute'>
        <pose frame=''>0 0 0 0 -0 0</pose>
        <parent>arm_link_2</parent>
        <child>arm_link_3</child>
        <axis>
          <dynamics>
            <damping>1</damping>
            <friction>0</friction>
            <spring_reference>0</spring_reference>
            <spring_stiffness>0</spring_stiffness>
          </dynamics>
          <limit>
            <lower>-5.18363</lower>
            <upper>0</upper>
            <effort>6</effort>
            <velocity>-1</velocity>
          </limit>
          <xyz>-0.173648 -0.984808 0</xyz>
          <use_parent_model_frame>1</use_parent_model_frame>
        </axis>
      </joint>
      <joint name='arm_joint_4' type='revolute'>
        <pose frame=''>0 0 0 0 -0 0</pose>
        <parent>arm_link_3</parent>
        <child>arm_link_4</child>
        <axis>
          <dynamics>
            <damping>1</damping>
            <friction>0</friction>
            <spring_reference>0</spring_reference>
            <spring_stiffness>0</spring_stiffness>
          </dynamics>
          <limit>
            <lower>0</lower>
            <upper>3.57793</upper>
            <effort>2</effort>
            <velocity>-1</velocity>
          </limit>
          <xyz>-0.173648 -0.984808 0</xyz>
          <use_parent_model_frame>1</use_parent_model_frame>
        </axis>
      </joint>
      <joint name='arm_joint_5' type='revolute'>
        <pose frame=''>0 0 0 0 -0 0</pose>
        <parent>arm_link_4</parent>
        <child>arm_link_5</child>
        <axis>
          <dynamics>
            <damping>1</damping>
            <friction>0</friction>
            <spring_reference>0</spring_reference>
            <spring_stiffness>0</spring_stiffness>
          </dynamics>
          <limit>
            <lower>0</lower>
            <upper>5.84685</upper>
            <effort>1</effort>
            <velocity>-1</velocity>
          </limit>
          <xyz>-0.360933 0.063642 -0.930418</xyz>
          <use_parent_model_frame>1</use_parent_model_frame>
        </axis>
      </joint>
      <joint name='gripper_palm_joint' type='revolute'>
        <pose frame=''>0 0 0 0 -0 0</pose>
        <parent>arm_link_5</parent>
        <child>gripper_palm_link</child>
        <axis>
          <dynamics>
            <damping>0</damping>
            <friction>0</friction>
            <spring_reference>0</spring_reference>
            <spring_stiffness>0</spring_stiffness>
          </dynamics>
          <limit>
            <lower>0</lower>
            <upper>0</upper>
            <effort>0</effort>
            <velocity>0</velocity>
          </limit>
          <xyz>0 0 1</xyz>
          <use_parent_model_frame>1</use_parent_model_frame>
        </axis>
      </joint>
      <joint name='gripper_finger_joint_l' type='prismatic'>
        <pose frame=''>0 0 0 0 -0 0</pose>
        <parent>gripper_palm_link</parent>
        <child>gripper_finger_link_l</child>
        <axis>
          <dynamics>
            <damping>1</damping>
            <friction>0</friction>
            <spring_reference>0</spring_reference>
            <spring_stiffness>0</spring_stiffness>
          </dynamics>
          <limit>
            <lower>0</lower>
            <upper>0.0115</upper>
            <effort>1</effort>
            <velocity>-1</velocity>
          </limit>
          <xyz>0.367852 0.926495 -0.079325</xyz>
          <use_parent_model_frame>1</use_parent_model_frame>
        </axis>
      </joint>
      <joint name='gripper_finger_joint_r' type='prismatic'>
        <pose frame=''>0 0 0 0 -0 0</pose>
        <parent>gripper_palm_link</parent>
        <child>gripper_finger_link_r</child>
        <axis>
          <dynamics>
            <damping>1</damping>
            <friction>0</friction>
            <spring_reference>0</spring_reference>
            <spring_stiffness>0</spring_stiffness>
          </dynamics>
          <limit>
            <lower>0</lower>
            <upper>0.0115</upper>
            <effort>1</effort>
            <velocity>-1</velocity>
          </limit>
          <xyz>-0.367852 -0.926495 0.079325</xyz>
          <use_parent_model_frame>1</use_parent_model_frame>
        </axis>
      </joint>
      <joint name='base_laser_front_hokuyo_urg04_laser_joint' type='revolute'>
        <pose frame=''>0 0 0 0 -0 0</pose>
        <parent>base_link</parent>
        <child>base_laser_front_link</child>
        <axis>
          <dynamics>
            <damping>0</damping>
            <friction>0</friction>
            <spring_reference>0</spring_reference>
            <spring_stiffness>0</spring_stiffness>
          </dynamics>
          <limit>
            <lower>0</lower>
            <upper>0</upper>
            <effort>0</effort>
            <velocity>0</velocity>
          </limit>
          <xyz>0 0 1</xyz>
          <use_parent_model_frame>1</use_parent_model_frame>
        </axis>
      </joint>
      <joint name='caster_joint_bl' type='revolute'>
        <pose frame=''>0 0 0 0 -0 0</pose>
        <parent>base_link</parent>
        <child>caster_link_bl</child>
        <axis>
          <dynamics>
            <damping>1</damping>
            <friction>0</friction>
            <spring_reference>0</spring_reference>
            <spring_stiffness>0</spring_stiffness>
          </dynamics>
          <limit>
            <effort>1</effort>
            <lower>-1e+16</lower>
            <upper>1e+16</upper>
          </limit>
          <xyz>0 0 1</xyz>
          <use_parent_model_frame>1</use_parent_model_frame>
        </axis>
      </joint>
      <joint name='wheel_joint_bl' type='revolute'>
        <pose frame=''>0 0 0 0 -0 0</pose>
        <parent>caster_link_bl</parent>
        <child>wheel_link_bl</child>
        <axis>
          <dynamics>
            <damping>1</damping>
            <friction>0</friction>
            <spring_reference>0</spring_reference>
            <spring_stiffness>0</spring_stiffness>
          </dynamics>
          <limit>
            <effort>1</effort>
            <lower>-1e+16</lower>
            <upper>1e+16</upper>
          </limit>
          <xyz>0 1 0</xyz>
          <use_parent_model_frame>1</use_parent_model_frame>
        </axis>
      </joint>
      <joint name='caster_joint_br' type='revolute'>
        <pose frame=''>0 0 0 0 -0 0</pose>
        <parent>base_link</parent>
        <child>caster_link_br</child>
        <axis>
          <dynamics>
            <damping>1</damping>
            <friction>0</friction>
            <spring_reference>0</spring_reference>
            <spring_stiffness>0</spring_stiffness>
          </dynamics>
          <limit>
            <effort>1</effort>
            <lower>-1e+16</lower>
            <upper>1e+16</upper>
          </limit>
          <xyz>0 0 1</xyz>
          <use_parent_model_frame>1</use_parent_model_frame>
        </axis>
      </joint>
      <joint name='wheel_joint_br' type='revolute'>
        <pose frame=''>0 0 0 0 -0 0</pose>
        <parent>caster_link_br</parent>
        <child>wheel_link_br</child>
        <axis>
          <dynamics>
            <damping>1</damping>
            <friction>0</friction>
            <spring_reference>0</spring_reference>
            <spring_stiffness>0</spring_stiffness>
          </dynamics>
          <limit>
            <effort>1</effort>
            <lower>-1e+16</lower>
            <upper>1e+16</upper>
          </limit>
          <xyz>0 1 0</xyz>
          <use_parent_model_frame>1</use_parent_model_frame>
        </axis>
      </joint>
      <joint name='caster_joint_fl' type='revolute'>
        <pose frame=''>0 0 0 0 -0 0</pose>
        <parent>base_link</parent>
        <child>caster_link_fl</child>
        <axis>
          <dynamics>
            <damping>1</damping>
            <friction>0</friction>
            <spring_reference>0</spring_reference>
            <spring_stiffness>0</spring_stiffness>
          </dynamics>
          <limit>
            <effort>1</effort>
            <lower>-1e+16</lower>
            <upper>1e+16</upper>
          </limit>
          <xyz>0 0 1</xyz>
          <use_parent_model_frame>1</use_parent_model_frame>
        </axis>
      </joint>
      <joint name='wheel_joint_fl' type='revolute'>
        <pose frame=''>0 0 0 0 -0 0</pose>
        <parent>caster_link_fl</parent>
        <child>wheel_link_fl</child>
        <axis>
          <dynamics>
            <damping>1</damping>
            <friction>0</friction>
            <spring_reference>0</spring_reference>
            <spring_stiffness>0</spring_stiffness>
          </dynamics>
          <limit>
            <effort>1</effort>
            <lower>-1e+16</lower>
            <upper>1e+16</upper>
          </limit>
          <xyz>0 1 0</xyz>
          <use_parent_model_frame>1</use_parent_model_frame>
        </axis>
      </joint>
      <joint name='caster_joint_fr' type='revolute'>
        <pose frame=''>0 0 0 0 -0 0</pose>
        <parent>base_link</parent>
        <child>caster_link_fr</child>
        <axis>
          <dynamics>
            <damping>1</damping>
            <friction>0</friction>
            <spring_reference>0</spring_reference>
            <spring_stiffness>0</spring_stiffness>
          </dynamics>
          <limit>
            <effort>1</effort>
            <lower>-1e+16</lower>
            <upper>1e+16</upper>
          </limit>
          <xyz>0 0 1</xyz>
          <use_parent_model_frame>1</use_parent_model_frame>
        </axis>
      </joint>
      <joint name='wheel_joint_fr' type='revolute'>
        <pose frame=''>0 0 0 0 -0 0</pose>
        <parent>caster_link_fr</parent>
        <child>wheel_link_fr</child>
        <axis>
          <dynamics>
            <damping>1</damping>
            <friction>0</friction>
            <spring_reference>0</spring_reference>
            <spring_stiffness>0</spring_stiffness>
          </dynamics>
          <limit>
            <effort>1</effort>
            <lower>-1e+16</lower>
            <upper>1e+16</upper>
          </limit>
          <xyz>0 1 0</xyz>
          <use_parent_model_frame>1</use_parent_model_frame>
        </axis>
      </joint>
      <joint name='plate_joint' type='revolute'>
        <parent>base_link</parent>
        <child>plate_link</child>
        <axis>
          <dynamics>
            <damping>0</damping>
            <friction>0</friction>
            <spring_reference>0</spring_reference>
            <spring_stiffness>0</spring_stiffness>
          </dynamics>
          <limit>
            <lower>0</lower>
            <upper>0</upper>
            <effort>0</effort>
            <velocity>0</velocity>
          </limit>
          <xyz>0 0 1</xyz>
          <use_parent_model_frame>1</use_parent_model_frame>
        </axis>
      </joint>
      <static>0</static>
    </model>
    <model name='wooden_case_wooden_peg'>
      <link name='wooden_case::base'>
        <pose frame=''>0 0 0.024 0 -0 0</pose>
        <inertial>
          <pose frame=''>-0.022184 0 0.171592 0 -0 0</pose>
          <mass>3.96264</mass>
          <inertia>
            <ixx>0.213536</ixx>
            <ixy>0</ixy>
            <ixz>0.000779377</ixz>
            <iyy>0.0708943</iyy>
            <iyz>0</iyz>
            <izz>0.154604</izz>
          </inertia>
        </inertial>
        <collision name='collision_back'>
          <pose frame=''>-0.053975 0 0.1778 0 -0 0</pose>
          <geometry>
            <box>
              <size>0.01905 0.5461 0.3175</size>
            </box>
          </geometry>
          <surface>
            <contact>
              <poissons_ratio>0.347</poissons_ratio>
              <elastic_modulus>8.8e+09</elastic_modulus>
              <ode>
                <kp>100000</kp>
                <kd>100</kd>
                <max_vel>100</max_vel>
                <min_depth>0.001</min_depth>
              </ode>
            </contact>
            <friction>
              <torsional>
                <coefficient>1</coefficient>
                <use_patch_radius>0</use_patch_radius>
                <surface_radius>0.01</surface_radius>
                <ode/>
              </torsional>
              <ode/>
            </friction>
            <bounce/>
          </surface>
          <max_contacts>10</max_contacts>
        </collision>
        <visual name='visual_back'>
          <pose frame=''>-0.053975 0 0.1778 0 -0 0</pose>
          <geometry>
            <box>
              <size>0.01905 0.5461 0.3175</size>
            </box>
          </geometry>
          <material>
            <script>
              <uri>file://media/materials/scripts/gazebo.material</uri>
              <name>Gazebo/Wood</name>
            </script>
          </material>
        </visual>
        <collision name='collision_bottom'>
          <pose frame=''>0 0 0.009525 0 -0 0</pose>
          <geometry>
            <box>
              <size>0.127 0.5842 0.01905</size>
            </box>
          </geometry>
          <surface>
            <contact>
              <poissons_ratio>0.347</poissons_ratio>
              <elastic_modulus>8.8e+09</elastic_modulus>
              <ode>
                <kp>100000</kp>
                <kd>100</kd>
                <max_vel>100</max_vel>
                <min_depth>0.001</min_depth>
              </ode>
            </contact>
            <friction>
              <torsional>
                <coefficient>1</coefficient>
                <use_patch_radius>0</use_patch_radius>
                <surface_radius>0.01</surface_radius>
                <ode/>
              </torsional>
              <ode/>
            </friction>
            <bounce/>
          </surface>
          <max_contacts>10</max_contacts>
        </collision>
        <visual name='visual_bottom'>
          <pose frame=''>0 0 0.009525 0 -0 0</pose>
          <geometry>
            <box>
              <size>0.127 0.5842 0.01905</size>
            </box>
          </geometry>
          <material>
            <script>
              <uri>file://media/materials/scripts/gazebo.material</uri>
              <name>Gazebo/Wood</name>
            </script>
          </material>
        </visual>
        <collision name='collision_top'>
          <pose frame=''>0 0 0.346075 0 -0 0</pose>
          <geometry>
            <box>
              <size>0.127 0.5842 0.01905</size>
            </box>
          </geometry>
          <surface>
            <contact>
              <poissons_ratio>0.347</poissons_ratio>
              <elastic_modulus>8.8e+09</elastic_modulus>
              <ode>
                <kp>100000</kp>
                <kd>100</kd>
                <max_vel>100</max_vel>
                <min_depth>0.001</min_depth>
              </ode>
            </contact>
            <friction>
              <torsional>
                <coefficient>1</coefficient>
                <use_patch_radius>0</use_patch_radius>
                <surface_radius>0.01</surface_radius>
                <ode/>
              </torsional>
              <ode/>
            </friction>
            <bounce/>
          </surface>
          <max_contacts>10</max_contacts>
        </collision>
        <visual name='visual_top'>
          <pose frame=''>0 0 0.346075 0 -0 0</pose>
          <geometry>
            <box>
              <size>0.127 0.5842 0.01905</size>
            </box>
          </geometry>
          <material>
            <script>
              <uri>file://media/materials/scripts/gazebo.material</uri>
              <name>Gazebo/Wood</name>
            </script>
          </material>
        </visual>
        <collision name='collision_left'>
          <pose frame=''>0 -0.282575 0.1778 0 -0 0</pose>
          <geometry>
            <box>
              <size>0.127 0.01905 0.3175</size>
            </box>
          </geometry>
          <surface>
            <contact>
              <poissons_ratio>0.347</poissons_ratio>
              <elastic_modulus>8.8e+09</elastic_modulus>
              <ode>
                <kp>100000</kp>
                <kd>100</kd>
                <max_vel>100</max_vel>
                <min_depth>0.001</min_depth>
              </ode>
            </contact>
            <friction>
              <torsional>
                <coefficient>1</coefficient>
                <use_patch_radius>0</use_patch_radius>
                <surface_radius>0.01</surface_radius>
                <ode/>
              </torsional>
              <ode/>
            </friction>
            <bounce/>
          </surface>
          <max_contacts>10</max_contacts>
        </collision>
        <visual name='visual_left'>
          <pose frame=''>0 -0.282575 0.1778 0 -0 0</pose>
          <geometry>
            <box>
              <size>0.127 0.01905 0.3175</size>
            </box>
          </geometry>
          <material>
            <script>
              <uri>file://media/materials/scripts/gazebo.material</uri>
              <name>Gazebo/Wood</name>
            </script>
          </material>
        </visual>
        <collision name='collision_right'>
          <pose frame=''>0 0.282575 0.1778 0 -0 0</pose>
          <geometry>
            <box>
              <size>0.127 0.01905 0.3175</size>
            </box>
          </geometry>
          <surface>
            <contact>
              <poissons_ratio>0.347</poissons_ratio>
              <elastic_modulus>8.8e+09</elastic_modulus>
              <ode>
                <kp>100000</kp>
                <kd>100</kd>
                <max_vel>100</max_vel>
                <min_depth>0.001</min_depth>
              </ode>
            </contact>
            <friction>
              <torsional>
                <coefficient>1</coefficient>
                <use_patch_radius>0</use_patch_radius>
                <surface_radius>0.01</surface_radius>
                <ode/>
              </torsional>
              <ode/>
            </friction>
            <bounce/>
          </surface>
          <max_contacts>10</max_contacts>
        </collision>
        <visual name='visual_right'>
          <pose frame=''>0 0.282575 0.1778 0 -0 0</pose>
          <geometry>
            <box>
              <size>0.127 0.01905 0.3175</size>
            </box>
          </geometry>
          <material>
            <script>
              <uri>file://media/materials/scripts/gazebo.material</uri>
              <name>Gazebo/Wood</name>
            </script>
          </material>
        </visual>
        <collision name='collision_block_left'>
          <pose frame=''>0.0095 -0.2151 -0.012 0 -0 0</pose>
          <geometry>
            <box>
              <size>0.108 0.05 0.024</size>
            </box>
          </geometry>
          <surface>
            <contact>
              <poissons_ratio>0.347</poissons_ratio>
              <elastic_modulus>8.8e+09</elastic_modulus>
              <ode>
                <kp>100000</kp>
                <kd>100</kd>
                <max_vel>100</max_vel>
                <min_depth>0.001</min_depth>
              </ode>
            </contact>
            <friction>
              <torsional>
                <coefficient>1</coefficient>
                <use_patch_radius>0</use_patch_radius>
                <surface_radius>0.01</surface_radius>
                <ode/>
              </torsional>
              <ode/>
            </friction>
            <bounce/>
          </surface>
          <max_contacts>10</max_contacts>
        </collision>
        <visual name='visual_block_left'>
          <pose frame=''>0.0095 -0.2151 -0.012 0 -0 0</pose>
          <geometry>
            <box>
              <size>0.108 0.05 0.024</size>
            </box>
          </geometry>
          <material>
            <script>
              <uri>file://media/materials/scripts/gazebo.material</uri>
              <name>Gazebo/Wood</name>
            </script>
          </material>
        </visual>
        <collision name='collision_block_right'>
          <pose frame=''>0.0095 0.2151 -0.012 0 -0 0</pose>
          <geometry>
            <box>
              <size>0.108 0.05 0.024</size>
            </box>
          </geometry>
          <surface>
            <contact>
              <poissons_ratio>0.347</poissons_ratio>
              <elastic_modulus>8.8e+09</elastic_modulus>
              <ode>
                <kp>100000</kp>
                <kd>100</kd>
                <max_vel>100</max_vel>
                <min_depth>0.001</min_depth>
              </ode>
            </contact>
            <friction>
              <torsional>
                <coefficient>1</coefficient>
                <use_patch_radius>0</use_patch_radius>
                <surface_radius>0.01</surface_radius>
                <ode/>
              </torsional>
              <ode/>
            </friction>
            <bounce/>
          </surface>
          <max_contacts>10</max_contacts>
        </collision>
        <visual name='visual_block_right'>
          <pose frame=''>0.0095 0.2151 -0.012 0 -0 0</pose>
          <geometry>
            <box>
              <size>0.108 0.05 0.024</size>
            </box>
          </geometry>
          <material>
            <script>
              <uri>file://media/materials/scripts/gazebo.material</uri>
              <name>Gazebo/Wood</name>
            </script>
          </material>
        </visual>
        <self_collide>0</self_collide>
        <kinematic>0</kinematic>
      </link>
      <link name='wooden_case::lid'>
        <pose frame=''>0.243775 0 0.009525 0 -0 0</pose>
        <inertial>
          <mass>1.97874</mass>
          <inertia>
            <ixx>0.0563367</ixx>
            <ixy>0</ixy>
            <ixz>0</ixz>
            <iyy>0.020911</iyy>
            <iyz>0</iyz>
            <izz>0.0771281</izz>
          </inertia>
        </inertial>
        <collision name='collision'>
          <geometry>
            <box>
              <size>0.3556 0.5842 0.01905</size>
            </box>
          </geometry>
          <surface>
            <contact>
              <poissons_ratio>0.347</poissons_ratio>
              <elastic_modulus>8.8e+09</elastic_modulus>
              <ode>
                <kp>100000</kp>
                <kd>100</kd>
                <max_vel>100</max_vel>
                <min_depth>0.001</min_depth>
              </ode>
            </contact>
            <friction>
              <torsional>
                <coefficient>1</coefficient>
                <use_patch_radius>0</use_patch_radius>
                <surface_radius>0.01</surface_radius>
                <ode/>
              </torsional>
              <ode/>
            </friction>
            <bounce/>
          </surface>
          <max_contacts>10</max_contacts>
        </collision>
        <visual name='visual'>
          <geometry>
            <box>
              <size>0.3556 0.5842 0.01905</size>
            </box>
          </geometry>
          <material>
            <script>
              <uri>file://media/materials/scripts/gazebo.material</uri>
              <name>Gazebo/Wood</name>
            </script>
          </material>
        </visual>
        <visual name='tee_nut_1'>
          <pose frame=''>0.122 -0.216 0 0 -0 0</pose>
          <geometry>
            <cylinder>
              <radius>0.00635</radius>
              <length>0.0192405</length>
            </cylinder>
          </geometry>
          <material>
            <script>
              <uri>file://media/materials/scripts/gazebo.material</uri>
              <name>Gazebo/Grey</name>
            </script>
          </material>
        </visual>
        <visual name='tee_nut_2'>
          <pose frame=''>0.122 -0.088 0 0 -0 0</pose>
          <geometry>
            <cylinder>
              <radius>0.00635</radius>
              <length>0.0192405</length>
            </cylinder>
          </geometry>
          <material>
            <script>
              <uri>file://media/materials/scripts/gazebo.material</uri>
              <name>Gazebo/Grey</name>
            </script>
          </material>
        </visual>
        <visual name='tee_nut_3'>
          <pose frame=''>0.122 0.088 0 0 -0 0</pose>
          <geometry>
            <cylinder>
              <radius>0.00635</radius>
              <length>0.0192405</length>
            </cylinder>
          </geometry>
          <material>
            <script>
              <uri>file://media/materials/scripts/gazebo.material</uri>
              <name>Gazebo/Grey</name>
            </script>
          </material>
        </visual>
        <visual name='tee_nut_4'>
          <pose frame=''>0.122 0.216 0 0 -0 0</pose>
          <geometry>
            <cylinder>
              <radius>0.00635</radius>
              <length>0.0192405</length>
            </cylinder>
          </geometry>
          <material>
            <script>
              <uri>file://media/materials/scripts/gazebo.material</uri>
              <name>Gazebo/Grey</name>
            </script>
          </material>
        </visual>
        <self_collide>0</self_collide>
        <kinematic>0</kinematic>
      </link>
      <joint name='wooden_case::lid_hinge' type='revolute'>
        <pose frame=''>-0.1778 0 0.01905 0 -0 0</pose>
        <parent>wooden_case::base</parent>
        <child>wooden_case::lid</child>
        <axis>
          <xyz>0 1 0</xyz>
          <limit>
            <upper>0.523599</upper>
            <lower>-1.5708</lower>
          </limit>
          <use_parent_model_frame>0</use_parent_model_frame>
          <dynamics>
            <spring_reference>0</spring_reference>
            <spring_stiffness>0</spring_stiffness>
          </dynamics>
        </axis>
      </joint>
      <link name='peg::link'>
        <pose frame=''>0.365774 0.216 0.05905 0 -0 0</pose>
        <inertial>
          <mass>0.0175</mass>
          <inertia>
            <ixx>9.74923e-06</ixx>
            <ixy>0</ixy>
            <ixz>0</ixz>
            <iyy>9.74923e-06</iyy>
            <iyz>0</iyz>
            <izz>8.31797e-07</izz>
          </inertia>
        </inertial>
        <collision name='collision'>
          <geometry>
            <cylinder>
              <radius>0.00975</radius>
              <length>0.08</length>
            </cylinder>
          </geometry>
          <surface>
            <contact>
              <poissons_ratio>0.347</poissons_ratio>
              <elastic_modulus>8.8e+09</elastic_modulus>
              <ode>
                <kp>100000</kp>
                <kd>100</kd>
                <max_vel>100</max_vel>
                <min_depth>0.001</min_depth>
              </ode>
            </contact>
            <friction>
              <torsional>
                <coefficient>1</coefficient>
                <use_patch_radius>0</use_patch_radius>
                <surface_radius>0.01</surface_radius>
                <ode/>
              </torsional>
              <ode/>
            </friction>
            <bounce/>
          </surface>
          <max_contacts>10</max_contacts>
        </collision>
        <visual name='visual'>
          <geometry>
            <cylinder>
              <radius>0.00975</radius>
              <length>0.08</length>
            </cylinder>
          </geometry>
          <material>
            <script>
              <uri>file://media/materials/scripts/gazebo.material</uri>
              <name>Gazebo/Wood</name>
            </script>
          </material>
        </visual>
        <self_collide>0</self_collide>
        <kinematic>0</kinematic>
      </link>
      <joint name='case_peg' type='revolute'>
        <child>peg::link</child>
        <parent>wooden_case::lid</parent>
        <axis>
          <xyz>0 0 1</xyz>
          <limit>
            <upper>0</upper>
            <lower>0</lower>
          </limit>
          <use_parent_model_frame>0</use_parent_model_frame>
          <dynamics>
            <spring_reference>0</spring_reference>
            <spring_stiffness>0</spring_stiffness>
          </dynamics>
        </axis>
      </joint>
      <pose frame=''>-1.50248 2.02358 0 0 -0 0</pose>
    </model>
    <model name='water_tower'>
      <static>1</static>
      <link name='link'>
        <collision name='collision'>
          <geometry>
            <mesh>
              <uri>model://water_tower/meshes/water_tower.dae</uri>
            </mesh>
          </geometry>
          <max_contacts>10</max_contacts>
          <surface>
            <contact>
              <ode/>
            </contact>
            <bounce/>
            <friction>
              <torsional>
                <ode/>
              </torsional>
              <ode/>
            </friction>
          </surface>
        </collision>
        <visual name='visual'>
          <geometry>
            <mesh>
              <uri>model://water_tower/meshes/water_tower.dae</uri>
            </mesh>
          </geometry>
        </visual>
        <self_collide>0</self_collide>
        <kinematic>0</kinematic>
      </link>
      <pose frame=''>4.73599 0.565297 0 0 -0 0</pose>
    </model>
    <model name='truss_bridge'>
      <static>1</static>
      <link name='link'>
        <collision name='collision'>
          <geometry>
            <mesh>
              <uri>model://truss_bridge/meshes/truss_bridge.dae</uri>
            </mesh>
          </geometry>
          <max_contacts>10</max_contacts>
          <surface>
            <contact>
              <ode/>
            </contact>
            <bounce/>
            <friction>
              <torsional>
                <ode/>
              </torsional>
              <ode/>
            </friction>
          </surface>
        </collision>
        <visual name='visual'>
          <geometry>
            <mesh>
              <uri>model://truss_bridge/meshes/truss_bridge.dae</uri>
            </mesh>
          </geometry>
        </visual>
        <self_collide>0</self_collide>
        <kinematic>0</kinematic>
      </link>
      <pose frame=''>-5.71203 0.106755 0 0 -0 0</pose>
    </model>
    <model name='car'>
      <link name='chassis'>
        <pose frame=''>0 0 0.3 0 -0 0</pose>
        <collision name='collision'>
          <geometry>
            <box>
              <size>2 1 0.2</size>
            </box>
          </geometry>
          <max_contacts>10</max_contacts>
          <surface>
            <contact>
              <ode/>
            </contact>
            <bounce/>
            <friction>
              <torsional>
                <ode/>
              </torsional>
              <ode/>
            </friction>
          </surface>
        </collision>
        <visual name='visual'>
          <geometry>
            <box>
              <size>2 1 0.2</size>
            </box>
          </geometry>
          <material>
            <script>
              <uri>file://media/materials/scripts/gazebo.material</uri>
              <name>Gazebo/Green</name>
            </script>
          </material>
        </visual>
        <self_collide>0</self_collide>
        <inertial>
          <inertia>
            <ixx>1</ixx>
            <ixy>0</ixy>
            <ixz>0</ixz>
            <iyy>1</iyy>
            <iyz>0</iyz>
            <izz>1</izz>
          </inertia>
          <mass>1</mass>
        </inertial>
        <kinematic>0</kinematic>
      </link>
      <link name='front_left_wheel'>
        <pose frame=''>0.8 0.6 0.3 -0 1.5707 1.5707</pose>
        <collision name='collision'>
          <geometry>
            <cylinder>
              <radius>0.3</radius>
              <length>0.1</length>
            </cylinder>
          </geometry>
          <max_contacts>10</max_contacts>
          <surface>
            <contact>
              <ode/>
            </contact>
            <bounce/>
            <friction>
              <torsional>
                <ode/>
              </torsional>
              <ode/>
            </friction>
          </surface>
        </collision>
        <visual name='visual'>
          <geometry>
            <cylinder>
              <radius>0.3</radius>
              <length>0.1</length>
            </cylinder>
          </geometry>
          <material>
            <script>
              <uri>file://media/materials/scripts/gazebo.material</uri>
              <name>Gazebo/Black</name>
            </script>
          </material>
        </visual>
        <self_collide>0</self_collide>
        <inertial>
          <inertia>
            <ixx>1</ixx>
            <ixy>0</ixy>
            <ixz>0</ixz>
            <iyy>1</iyy>
            <iyz>0</iyz>
            <izz>1</izz>
          </inertia>
          <mass>1</mass>
        </inertial>
        <kinematic>0</kinematic>
      </link>
      <link name='front_right_wheel'>
        <pose frame=''>0.8 -0.6 0.3 -0 1.5707 1.5707</pose>
        <collision name='collision'>
          <geometry>
            <cylinder>
              <radius>0.3</radius>
              <length>0.1</length>
            </cylinder>
          </geometry>
          <max_contacts>10</max_contacts>
          <surface>
            <contact>
              <ode/>
            </contact>
            <bounce/>
            <friction>
              <torsional>
                <ode/>
              </torsional>
              <ode/>
            </friction>
          </surface>
        </collision>
        <visual name='visual'>
          <geometry>
            <cylinder>
              <radius>0.3</radius>
              <length>0.1</length>
            </cylinder>
          </geometry>
          <material>
            <script>
              <uri>file://media/materials/scripts/gazebo.material</uri>
              <name>Gazebo/Black</name>
            </script>
          </material>
        </visual>
        <self_collide>0</self_collide>
        <inertial>
          <inertia>
            <ixx>1</ixx>
            <ixy>0</ixy>
            <ixz>0</ixz>
            <iyy>1</iyy>
            <iyz>0</iyz>
            <izz>1</izz>
          </inertia>
          <mass>1</mass>
        </inertial>
        <kinematic>0</kinematic>
      </link>
      <link name='back_right_wheel'>
        <pose frame=''>-0.8 -0.6 0.3 -0 1.5707 1.5707</pose>
        <collision name='collision'>
          <geometry>
            <cylinder>
              <radius>0.3</radius>
              <length>0.1</length>
            </cylinder>
          </geometry>
          <max_contacts>10</max_contacts>
          <surface>
            <contact>
              <ode/>
            </contact>
            <bounce/>
            <friction>
              <torsional>
                <ode/>
              </torsional>
              <ode/>
            </friction>
          </surface>
        </collision>
        <visual name='visual'>
          <geometry>
            <cylinder>
              <radius>0.3</radius>
              <length>0.1</length>
            </cylinder>
          </geometry>
          <material>
            <script>
              <uri>file://media/materials/scripts/gazebo.material</uri>
              <name>Gazebo/Black</name>
            </script>
          </material>
        </visual>
        <self_collide>0</self_collide>
        <inertial>
          <inertia>
            <ixx>1</ixx>
            <ixy>0</ixy>
            <ixz>0</ixz>
            <iyy>1</iyy>
            <iyz>0</iyz>
            <izz>1</izz>
          </inertia>
          <mass>1</mass>
        </inertial>
        <kinematic>0</kinematic>
      </link>
      <link name='back_left_wheel'>
        <pose frame=''>-0.8 0.6 0.3 -0 1.5707 1.5707</pose>
        <collision name='collision'>
          <geometry>
            <cylinder>
              <radius>0.3</radius>
              <length>0.1</length>
            </cylinder>
          </geometry>
          <max_contacts>10</max_contacts>
          <surface>
            <contact>
              <ode/>
            </contact>
            <bounce/>
            <friction>
              <torsional>
                <ode/>
              </torsional>
              <ode/>
            </friction>
          </surface>
        </collision>
        <visual name='visual'>
          <geometry>
            <cylinder>
              <radius>0.3</radius>
              <length>0.1</length>
            </cylinder>
          </geometry>
          <material>
            <script>
              <uri>file://media/materials/scripts/gazebo.material</uri>
              <name>Gazebo/Black</name>
            </script>
          </material>
        </visual>
        <self_collide>0</self_collide>
        <inertial>
          <inertia>
            <ixx>1</ixx>
            <ixy>0</ixy>
            <ixz>0</ixz>
            <iyy>1</iyy>
            <iyz>0</iyz>
            <izz>1</izz>
          </inertia>
          <mass>1</mass>
        </inertial>
        <kinematic>0</kinematic>
      </link>
      <link name='gas_pedal'>
        <pose frame=''>0.3 0.1 0.5 0 -0 0</pose>
        <collision name='collision'>
          <geometry>
            <box>
              <size>0.1 0.1 0.1</size>
            </box>
          </geometry>
          <max_contacts>10</max_contacts>
          <surface>
            <contact>
              <ode/>
            </contact>
            <bounce/>
            <friction>
              <torsional>
                <ode/>
              </torsional>
              <ode/>
            </friction>
          </surface>
        </collision>
        <visual name='visual'>
          <geometry>
            <box>
              <size>0.1 0.1 0.1</size>
            </box>
          </geometry>
          <material>
            <script>
              <uri>file://media/materials/scripts/gazebo.material</uri>
              <name>Gazebo/Red</name>
            </script>
          </material>
        </visual>
        <self_collide>0</self_collide>
        <inertial>
          <inertia>
            <ixx>1</ixx>
            <ixy>0</ixy>
            <ixz>0</ixz>
            <iyy>1</iyy>
            <iyz>0</iyz>
            <izz>1</izz>
          </inertia>
          <mass>1</mass>
        </inertial>
        <kinematic>0</kinematic>
      </link>
      <link name='brake_pedal'>
        <pose frame=''>0.3 0.25 0.5 0 -0 0</pose>
        <collision name='collision'>
          <geometry>
            <box>
              <size>0.1 0.1 0.1</size>
            </box>
          </geometry>
          <max_contacts>10</max_contacts>
          <surface>
            <contact>
              <ode/>
            </contact>
            <bounce/>
            <friction>
              <torsional>
                <ode/>
              </torsional>
              <ode/>
            </friction>
          </surface>
        </collision>
        <visual name='visual'>
          <geometry>
            <box>
              <size>0.1 0.1 0.1</size>
            </box>
          </geometry>
          <material>
            <script>
              <uri>file://media/materials/scripts/gazebo.material</uri>
              <name>Gazebo/Blue</name>
            </script>
          </material>
        </visual>
        <self_collide>0</self_collide>
        <inertial>
          <inertia>
            <ixx>1</ixx>
            <ixy>0</ixy>
            <ixz>0</ixz>
            <iyy>1</iyy>
            <iyz>0</iyz>
            <izz>1</izz>
          </inertia>
          <mass>1</mass>
        </inertial>
        <kinematic>0</kinematic>
      </link>
      <link name='steering_wheel'>
        <pose frame=''>0.3 0.2 1 0 1.5707 0</pose>
        <collision name='collision'>
          <geometry>
            <cylinder>
              <radius>0.1</radius>
              <length>0.01</length>
            </cylinder>
          </geometry>
          <max_contacts>10</max_contacts>
          <surface>
            <contact>
              <ode/>
            </contact>
            <bounce/>
            <friction>
              <torsional>
                <ode/>
              </torsional>
              <ode/>
            </friction>
          </surface>
        </collision>
        <visual name='visual'>
          <geometry>
            <cylinder>
              <radius>0.1</radius>
              <length>0.01</length>
            </cylinder>
          </geometry>
          <material>
            <script>
              <uri>file://media/materials/scripts/gazebo.material</uri>
              <name>Gazebo/Blue</name>
            </script>
          </material>
        </visual>
        <self_collide>0</self_collide>
        <inertial>
          <inertia>
            <ixx>1</ixx>
            <ixy>0</ixy>
            <ixz>0</ixz>
            <iyy>1</iyy>
            <iyz>0</iyz>
            <izz>1</izz>
          </inertia>
          <mass>1</mass>
        </inertial>
        <kinematic>0</kinematic>
      </link>
      <joint name='gas_joint' type='prismatic'>
        <parent>chassis</parent>
        <child>gas_pedal</child>
        <axis>
          <xyz>1 0 0</xyz>
          <limit>
            <lower>0</lower>
            <upper>0.2</upper>
          </limit>
          <use_parent_model_frame>1</use_parent_model_frame>
          <dynamics>
            <spring_reference>0</spring_reference>
            <spring_stiffness>0</spring_stiffness>
          </dynamics>
        </axis>
      </joint>
      <joint name='brake_joint' type='prismatic'>
        <parent>chassis</parent>
        <child>brake_pedal</child>
        <axis>
          <xyz>1 0 0</xyz>
          <limit>
            <lower>0</lower>
            <upper>0.2</upper>
          </limit>
          <use_parent_model_frame>1</use_parent_model_frame>
          <dynamics>
            <spring_reference>0</spring_reference>
            <spring_stiffness>0</spring_stiffness>
          </dynamics>
        </axis>
      </joint>
      <joint name='steering_joint' type='revolute'>
        <parent>chassis</parent>
        <child>steering_wheel</child>
        <axis>
          <xyz>1 0 0</xyz>
          <limit>
            <lower>-7.853</lower>
            <upper>7.853</upper>
          </limit>
          <use_parent_model_frame>1</use_parent_model_frame>
          <dynamics>
            <spring_reference>0</spring_reference>
            <spring_stiffness>0</spring_stiffness>
          </dynamics>
        </axis>
      </joint>
      <joint name='front_left_joint' type='revolute2'>
        <parent>chassis</parent>
        <child>front_left_wheel</child>
        <axis>
          <xyz>0 0 1</xyz>
          <limit>
            <lower>0</lower>
            <upper>0</upper>
          </limit>
          <use_parent_model_frame>1</use_parent_model_frame>
          <dynamics>
            <spring_reference>0</spring_reference>
            <spring_stiffness>0</spring_stiffness>
          </dynamics>
        </axis>
        <axis2>
          <xyz>0 1 0</xyz>
          <use_parent_model_frame>1</use_parent_model_frame>
          <dynamics>
            <spring_reference>0</spring_reference>
            <spring_stiffness>0</spring_stiffness>
          </dynamics>
        </axis2>
        <physics>
          <ode>
            <limit>
              <cfm>0</cfm>
              <erp>0.9</erp>
            </limit>
          </ode>
        </physics>
      </joint>
      <joint name='front_right_joint' type='revolute2'>
        <parent>chassis</parent>
        <child>front_right_wheel</child>
        <axis>
          <xyz>0 0 1</xyz>
          <limit>
            <lower>0</lower>
            <upper>0</upper>
          </limit>
          <use_parent_model_frame>1</use_parent_model_frame>
          <dynamics>
            <spring_reference>0</spring_reference>
            <spring_stiffness>0</spring_stiffness>
          </dynamics>
        </axis>
        <axis2>
          <xyz>0 1 0</xyz>
          <use_parent_model_frame>1</use_parent_model_frame>
          <dynamics>
            <spring_reference>0</spring_reference>
            <spring_stiffness>0</spring_stiffness>
          </dynamics>
        </axis2>
        <physics>
          <ode>
            <limit>
              <cfm>0</cfm>
              <erp>0.9</erp>
            </limit>
          </ode>
        </physics>
      </joint>
      <joint name='back_right_joint' type='revolute2'>
        <parent>chassis</parent>
        <child>back_right_wheel</child>
        <axis>
          <xyz>0 0 1</xyz>
          <limit>
            <lower>0</lower>
            <upper>0</upper>
          </limit>
          <use_parent_model_frame>1</use_parent_model_frame>
          <dynamics>
            <spring_reference>0</spring_reference>
            <spring_stiffness>0</spring_stiffness>
          </dynamics>
        </axis>
        <axis2>
          <xyz>0 1 0</xyz>
          <use_parent_model_frame>1</use_parent_model_frame>
          <dynamics>
            <spring_reference>0</spring_reference>
            <spring_stiffness>0</spring_stiffness>
          </dynamics>
        </axis2>
        <physics>
          <ode>
            <limit>
              <cfm>0</cfm>
              <erp>0.9</erp>
            </limit>
          </ode>
        </physics>
      </joint>
      <joint name='back_left_joint' type='revolute2'>
        <parent>chassis</parent>
        <child>back_left_wheel</child>
        <axis>
          <xyz>0 0 1</xyz>
          <limit>
            <lower>0</lower>
            <upper>0</upper>
          </limit>
          <use_parent_model_frame>1</use_parent_model_frame>
          <dynamics>
            <spring_reference>0</spring_reference>
            <spring_stiffness>0</spring_stiffness>
          </dynamics>
        </axis>
        <axis2>
          <xyz>0 1 0</xyz>
          <use_parent_model_frame>1</use_parent_model_frame>
          <dynamics>
            <spring_reference>0</spring_reference>
            <spring_stiffness>0</spring_stiffness>
          </dynamics>
        </axis2>
        <physics>
          <ode>
            <limit>
              <cfm>0</cfm>
              <erp>0.9</erp>
            </limit>
          </ode>
        </physics>
      </joint>
      <plugin name='vehicle' filename='libVehiclePlugin.so'>
        <front_left>front_left_joint</front_left>
        <front_right>front_right_joint</front_right>
        <back_left>back_left_joint</back_left>
        <back_right>back_right_joint</back_right>
        <gas>gas_joint</gas>
        <brake>brake_joint</brake>
        <steering>steering_joint</steering>
        <front_power>10</front_power>
        <rear_power>10</rear_power>
        <tire_angle_range>0.5</tire_angle_range>
        <max_speed>10</max_speed>
        <aero_load>0.1</aero_load>
      </plugin>
      <pose frame=''>1.79596 -5.96117 0 0 -0 0</pose>
    </model>
    <model name='warehouse_robot'>
      <static>1</static>
      <link name='link'>
        <visual name='visual'>
          <geometry>
            <mesh>
              <uri>model://warehouse_robot/meshes/robot.dae</uri>
            </mesh>
          </geometry>
        </visual>
        <collision name='collision_base'>
          <pose frame=''>0 0 0.20437 0 -0 0</pose>
          <geometry>
            <box>
              <size>0.55508 1.0228 0.40874</size>
            </box>
          </geometry>
          <max_contacts>10</max_contacts>
          <surface>
            <contact>
              <ode/>
            </contact>
            <bounce/>
            <friction>
              <torsional>
                <ode/>
              </torsional>
              <ode/>
            </friction>
          </surface>
        </collision>
        <collision name='collision_bumper'>
          <pose frame=''>0 0 0.062205 0 -0 0</pose>
          <geometry>
            <box>
              <size>0.67266 1.17126 0.12441</size>
            </box>
          </geometry>
          <max_contacts>10</max_contacts>
          <surface>
            <contact>
              <ode/>
            </contact>
            <bounce/>
            <friction>
              <torsional>
                <ode/>
              </torsional>
              <ode/>
            </friction>
          </surface>
        </collision>
        <collision name='collision_column_large'>
          <pose frame=''>0 -0.27539 0.43738 0 -0 0</pose>
          <geometry>
            <cylinder>
              <radius>0.08652</radius>
              <length>0.87476</length>
            </cylinder>
          </geometry>
          <max_contacts>10</max_contacts>
          <surface>
            <contact>
              <ode/>
            </contact>
            <bounce/>
            <friction>
              <torsional>
                <ode/>
              </torsional>
              <ode/>
            </friction>
          </surface>
        </collision>
        <collision name='collision_column_small'>
          <pose frame=''>0 -0.27539 0.70424 0 -0 0</pose>
          <geometry>
            <cylinder>
              <radius>0.04261</radius>
              <length>1.40848</length>
            </cylinder>
          </geometry>
          <max_contacts>10</max_contacts>
          <surface>
            <contact>
              <ode/>
            </contact>
            <bounce/>
            <friction>
              <torsional>
                <ode/>
              </torsional>
              <ode/>
            </friction>
          </surface>
        </collision>
        <self_collide>0</self_collide>
        <kinematic>0</kinematic>
      </link>
      <pose frame=''>6.49928 -5.99932 0 0 -0 0</pose>
    </model>
    <model name='wood_cube_10cm'>
      <link name='link'>
        <pose frame=''>0 0 0.05 0 -0 0</pose>
        <inertial>
          <mass>0.5167</mass>
          <inertia>
            <ixx>0.000861167</ixx>
            <ixy>0</ixy>
            <ixz>0</ixz>
            <iyy>0.000861167</iyy>
            <iyz>0</iyz>
            <izz>0.000861167</izz>
          </inertia>
        </inertial>
        <collision name='collision'>
          <geometry>
            <box>
              <size>0.1 0.1 0.1</size>
            </box>
          </geometry>
          <surface>
            <contact>
              <poissons_ratio>0.347</poissons_ratio>
              <elastic_modulus>8.8e+09</elastic_modulus>
              <ode>
                <kp>100000</kp>
                <kd>100</kd>
                <max_vel>100</max_vel>
                <min_depth>0.001</min_depth>
              </ode>
            </contact>
            <friction>
              <torsional>
                <coefficient>1</coefficient>
                <use_patch_radius>0</use_patch_radius>
                <surface_radius>0.01</surface_radius>
                <ode/>
              </torsional>
              <ode/>
            </friction>
            <bounce/>
          </surface>
          <max_contacts>10</max_contacts>
        </collision>
        <visual name='visual'>
          <geometry>
            <box>
              <size>0.1 0.1 0.1</size>
            </box>
          </geometry>
          <material>
            <script>
              <uri>file://media/materials/scripts/gazebo.material</uri>
              <name>Gazebo/Wood</name>
            </script>
          </material>
        </visual>
        <self_collide>0</self_collide>
        <kinematic>0</kinematic>
      </link>
      <pose frame=''>3.92861 -6.17078 0 0 -0 0</pose>
    </model>
    <model name='u_joint_part'>
      <pose frame=''>3.98792 -5.51985 0.07929 1.5707 -0 0</pose>
      <link name='link'>
        <inertial>
          <pose frame=''>0 0 0.08086 0 -0 0</pose>
          <mass>0.5</mass>
          <inertia>
            <ixx>0.00187559</ixx>
            <ixy>0</ixy>
            <ixz>0</ixz>
            <iyy>0.00187559</iyy>
            <iyz>0</iyz>
            <izz>0.00157173</izz>
          </inertia>
        </inertial>
        <collision name='collision1'>
          <pose frame=''>0 0 0.08086 0 -0 0</pose>
          <geometry>
            <cylinder>
              <radius>0.07929</radius>
              <length>0.16172</length>
            </cylinder>
          </geometry>
          <max_contacts>10</max_contacts>
          <surface>
            <contact>
              <ode/>
            </contact>
            <bounce/>
            <friction>
              <torsional>
                <ode/>
              </torsional>
              <ode/>
            </friction>
          </surface>
        </collision>
        <collision name='collision2'>
          <pose frame=''>-0.09124 0 0.22804 0 -0 0</pose>
          <geometry>
            <box>
              <size>0.01716 0.08862 0.13878</size>
            </box>
          </geometry>
          <max_contacts>10</max_contacts>
          <surface>
            <contact>
              <ode/>
            </contact>
            <bounce/>
            <friction>
              <torsional>
                <ode/>
              </torsional>
              <ode/>
            </friction>
          </surface>
        </collision>
        <collision name='collision3'>
          <pose frame=''>0.09124 0 0.22804 0 -0 0</pose>
          <geometry>
            <box>
              <size>0.01716 0.08862 0.13878</size>
            </box>
          </geometry>
          <max_contacts>10</max_contacts>
          <surface>
            <contact>
              <ode/>
            </contact>
            <bounce/>
            <friction>
              <torsional>
                <ode/>
              </torsional>
              <ode/>
            </friction>
          </surface>
        </collision>
        <visual name='visual'>
          <geometry>
            <mesh>
              <uri>model://u_joint_part/meshes/u_joint.dae</uri>
            </mesh>
          </geometry>
          <material>
            <script>
              <uri>model://arm_part/materials/scripts</uri>
              <uri>model://arm_part/materials/textures</uri>
              <name>ArmPart/Diffuse</name>
            </script>
          </material>
        </visual>
        <self_collide>0</self_collide>
        <kinematic>0</kinematic>
      </link>
    </model>
    <model name='trisphere_cycle'>
      <link name='frame'>
        <pose frame=''>-0.408559 0 0.385023 0 -0.522021 0</pose>
        <inertial>
          <pose frame=''>0 0 0 0 -0 0</pose>
          <mass>10</mass>
          <inertia>
            <ixx>0.228</ixx>
            <iyy>0.743521</iyy>
            <izz>0.965521</izz>
            <ixy>0</ixy>
            <ixz>0</ixz>
            <iyz>0</iyz>
          </inertia>
        </inertial>
        <collision name='axle_collision'>
          <pose frame=''>-0.471335 0 0 1.5708 -0 0</pose>
          <geometry>
            <cylinder>
              <length>1.03923</length>
              <radius>0.03</radius>
            </cylinder>
          </geometry>
          <max_contacts>10</max_contacts>
          <surface>
            <contact>
              <ode/>
            </contact>
            <bounce/>
            <friction>
              <torsional>
                <ode/>
              </torsional>
              <ode/>
            </friction>
          </surface>
        </collision>
        <visual name='axle_visual'>
          <pose frame=''>-0.471335 0 0 1.5708 -0 0</pose>
          <geometry>
            <cylinder>
              <length>1.03923</length>
              <radius>0.03</radius>
            </cylinder>
          </geometry>
          <material>
            <script>
              <uri>file://media/materials/scripts/gazebo.material</uri>
              <name>Gazebo/Grey</name>
            </script>
          </material>
        </visual>
        <collision name='frame_left_collision'>
          <pose frame=''>0 0.171552 0 -2.79253 1.57079 3.14159</pose>
          <geometry>
            <cylinder>
              <length>1.00317</length>
              <radius>0.03</radius>
            </cylinder>
          </geometry>
          <max_contacts>10</max_contacts>
          <surface>
            <contact>
              <ode/>
            </contact>
            <bounce/>
            <friction>
              <torsional>
                <ode/>
              </torsional>
              <ode/>
            </friction>
          </surface>
        </collision>
        <visual name='frame_left_visual'>
          <pose frame=''>0 0.171552 0 -2.79253 1.57079 3.14159</pose>
          <geometry>
            <cylinder>
              <length>1.00317</length>
              <radius>0.03</radius>
            </cylinder>
          </geometry>
          <material>
            <script>
              <uri>file://media/materials/scripts/gazebo.material</uri>
              <name>Gazebo/Grey</name>
            </script>
          </material>
        </visual>
        <collision name='frame_right_collision'>
          <pose frame=''>0 -0.171552 0 2.79253 1.57079 -3.14159</pose>
          <geometry>
            <cylinder>
              <length>1.00317</length>
              <radius>0.03</radius>
            </cylinder>
          </geometry>
          <max_contacts>10</max_contacts>
          <surface>
            <contact>
              <ode/>
            </contact>
            <bounce/>
            <friction>
              <torsional>
                <ode/>
              </torsional>
              <ode/>
            </friction>
          </surface>
        </collision>
        <visual name='frame_right_visual'>
          <pose frame=''>0 -0.171552 0 2.79253 1.57079 -3.14159</pose>
          <geometry>
            <cylinder>
              <length>1.00317</length>
              <radius>0.03</radius>
            </cylinder>
          </geometry>
          <material>
            <script>
              <uri>file://media/materials/scripts/gazebo.material</uri>
              <name>Gazebo/Grey</name>
            </script>
          </material>
        </visual>
        <self_collide>0</self_collide>
        <kinematic>0</kinematic>
      </link>
      <link name='fork'>
        <pose frame=''>0.041441 0 0.385023 0 -0.174533 0</pose>
        <inertial>
          <mass>3</mass>
          <inertia>
            <ixx>0.158203</ixx>
            <iyy>0.0583594</iyy>
            <izz>0.102656</izz>
            <ixy>0</ixy>
            <ixz>0</ixz>
            <iyz>0</iyz>
          </inertia>
        </inertial>
        <collision name='handlebars_collision'>
          <pose frame=''>0 0 0.397748 1.5708 -0 0</pose>
          <geometry>
            <cylinder>
              <length>0.636396</length>
              <radius>0.0375</radius>
            </cylinder>
          </geometry>
          <max_contacts>10</max_contacts>
          <surface>
            <contact>
              <ode/>
            </contact>
            <bounce/>
            <friction>
              <torsional>
                <ode/>
              </torsional>
              <ode/>
            </friction>
          </surface>
        </collision>
        <visual name='handlebars_visual'>
          <pose frame=''>0 0 0.397748 1.5708 -0 0</pose>
          <geometry>
            <cylinder>
              <length>0.636396</length>
              <radius>0.0375</radius>
            </cylinder>
          </geometry>
          <material>
            <script>
              <uri>file://media/materials/scripts/gazebo.material</uri>
              <name>Gazebo/Grey</name>
            </script>
          </material>
        </visual>
        <collision name='headtube_collision'>
          <pose frame=''>0 0 0.238649 0 -0 0</pose>
          <geometry>
            <cylinder>
              <length>0.318198</length>
              <radius>0.0375</radius>
            </cylinder>
          </geometry>
          <max_contacts>10</max_contacts>
          <surface>
            <contact>
              <ode/>
            </contact>
            <bounce/>
            <friction>
              <torsional>
                <ode/>
              </torsional>
              <ode/>
            </friction>
          </surface>
        </collision>
        <visual name='headtube_visual'>
          <pose frame=''>0 0 0.238649 0 -0 0</pose>
          <geometry>
            <cylinder>
              <length>0.318198</length>
              <radius>0.0375</radius>
            </cylinder>
          </geometry>
          <material>
            <script>
              <uri>file://media/materials/scripts/gazebo.material</uri>
              <name>Gazebo/Grey</name>
            </script>
          </material>
        </visual>
        <collision name='spindle_collision'>
          <pose frame=''>0 0 -0.238649 1.5708 -0 0</pose>
          <geometry>
            <cylinder>
              <length>0.636396</length>
              <radius>0.015</radius>
            </cylinder>
          </geometry>
          <max_contacts>10</max_contacts>
          <surface>
            <contact>
              <ode/>
            </contact>
            <bounce/>
            <friction>
              <torsional>
                <ode/>
              </torsional>
              <ode/>
            </friction>
          </surface>
        </collision>
        <visual name='spindle_visual'>
          <pose frame=''>0 0 -0.238649 1.5708 -0 0</pose>
          <geometry>
            <cylinder>
              <length>0.636396</length>
              <radius>0.015</radius>
            </cylinder>
          </geometry>
          <material>
            <script>
              <uri>file://media/materials/scripts/gazebo.material</uri>
              <name>Gazebo/Grey</name>
            </script>
          </material>
        </visual>
        <collision name='fork_left_collision'>
          <pose frame=''>0 0.159099 -0.07955 0.785398 -0 0</pose>
          <geometry>
            <cylinder>
              <length>0.45</length>
              <radius>0.0375</radius>
            </cylinder>
          </geometry>
          <max_contacts>10</max_contacts>
          <surface>
            <contact>
              <ode/>
            </contact>
            <bounce/>
            <friction>
              <torsional>
                <ode/>
              </torsional>
              <ode/>
            </friction>
          </surface>
        </collision>
        <visual name='fork_left_visual'>
          <pose frame=''>0 0.159099 -0.07955 0.785398 -0 0</pose>
          <geometry>
            <cylinder>
              <length>0.45</length>
              <radius>0.0375</radius>
            </cylinder>
          </geometry>
          <material>
            <script>
              <uri>file://media/materials/scripts/gazebo.material</uri>
              <name>Gazebo/Grey</name>
            </script>
          </material>
        </visual>
        <collision name='fork_right_collision'>
          <pose frame=''>0 -0.159099 -0.07955 -0.785398 0 0</pose>
          <geometry>
            <cylinder>
              <length>0.45</length>
              <radius>0.0375</radius>
            </cylinder>
          </geometry>
          <max_contacts>10</max_contacts>
          <surface>
            <contact>
              <ode/>
            </contact>
            <bounce/>
            <friction>
              <torsional>
                <ode/>
              </torsional>
              <ode/>
            </friction>
          </surface>
        </collision>
        <visual name='fork_right_visual'>
          <pose frame=''>0 -0.159099 -0.07955 -0.785398 0 0</pose>
          <geometry>
            <cylinder>
              <length>0.45</length>
              <radius>0.0375</radius>
            </cylinder>
          </geometry>
          <material>
            <script>
              <uri>file://media/materials/scripts/gazebo.material</uri>
              <name>Gazebo/Grey</name>
            </script>
          </material>
        </visual>
        <self_collide>0</self_collide>
        <kinematic>0</kinematic>
      </link>
      <link name='wheel_front'>
        <pose frame=''>0.082882 0 0.15 0 -0 0</pose>
        <inertial>
          <mass>0.5</mass>
          <inertia>
            <ixx>0.0045</ixx>
            <iyy>0.0045</iyy>
            <izz>0.0045</izz>
            <ixy>0</ixy>
            <ixz>0</ixz>
            <iyz>0</iyz>
          </inertia>
        </inertial>
        <collision name='collision'>
          <geometry>
            <sphere>
              <radius>0.15</radius>
            </sphere>
          </geometry>
          <surface>
            <contact>
              <ode>
                <kp>1e+08</kp>
                <kd>1</kd>
                <min_depth>0.0005</min_depth>
              </ode>
            </contact>
            <bounce/>
            <friction>
              <torsional>
                <ode/>
              </torsional>
              <ode/>
            </friction>
          </surface>
          <max_contacts>10</max_contacts>
        </collision>
        <visual name='visual'>
          <geometry>
            <sphere>
              <radius>0.15</radius>
            </sphere>
          </geometry>
          <material>
            <script>
              <uri>file://media/materials/scripts/gazebo.material</uri>
              <name>Gazebo/Black</name>
            </script>
          </material>
        </visual>
        <self_collide>0</self_collide>
        <kinematic>0</kinematic>
      </link>
      <joint name='wheel_front_steer' type='revolute'>
        <parent>frame</parent>
        <child>fork</child>
        <axis>
          <xyz>0 0 1</xyz>
          <limit>
            <lower>-0.959931</lower>
            <upper>0.959931</upper>
          </limit>
          <use_parent_model_frame>0</use_parent_model_frame>
          <dynamics>
            <spring_reference>0</spring_reference>
            <spring_stiffness>0</spring_stiffness>
          </dynamics>
        </axis>
      </joint>
      <joint name='wheel_front_spin' type='revolute'>
        <parent>fork</parent>
        <child>wheel_front</child>
        <axis>
          <xyz>0 1 0</xyz>
          <use_parent_model_frame>0</use_parent_model_frame>
          <limit>
            <lower>-1e+16</lower>
            <upper>1e+16</upper>
          </limit>
          <dynamics>
            <spring_reference>0</spring_reference>
            <spring_stiffness>0</spring_stiffness>
          </dynamics>
        </axis>
      </joint>
      <link name='wheel_rear_left'>
        <pose frame=''>-0.817118 0.519615 0.15 0 -0 0</pose>
        <inertial>
          <mass>0.5</mass>
          <inertia>
            <ixx>0.0045</ixx>
            <iyy>0.0045</iyy>
            <izz>0.0045</izz>
            <ixy>0</ixy>
            <ixz>0</ixz>
            <iyz>0</iyz>
          </inertia>
        </inertial>
        <collision name='collision'>
          <geometry>
            <sphere>
              <radius>0.15</radius>
            </sphere>
          </geometry>
          <surface>
            <contact>
              <ode>
                <kp>1e+08</kp>
                <kd>1</kd>
                <min_depth>0.0005</min_depth>
              </ode>
            </contact>
            <bounce/>
            <friction>
              <torsional>
                <ode/>
              </torsional>
              <ode/>
            </friction>
          </surface>
          <max_contacts>10</max_contacts>
        </collision>
        <visual name='visual'>
          <geometry>
            <sphere>
              <radius>0.15</radius>
            </sphere>
          </geometry>
          <material>
            <script>
              <uri>file://media/materials/scripts/gazebo.material</uri>
              <name>Gazebo/Black</name>
            </script>
          </material>
        </visual>
        <self_collide>0</self_collide>
        <kinematic>0</kinematic>
      </link>
      <joint name='wheel_rear_left_spin' type='revolute'>
        <parent>frame</parent>
        <child>wheel_rear_left</child>
        <axis>
          <xyz>0 1 0</xyz>
          <use_parent_model_frame>0</use_parent_model_frame>
          <limit>
            <lower>-1e+16</lower>
            <upper>1e+16</upper>
          </limit>
          <dynamics>
            <spring_reference>0</spring_reference>
            <spring_stiffness>0</spring_stiffness>
          </dynamics>
        </axis>
      </joint>
      <link name='wheel_rear_right'>
        <pose frame=''>-0.817118 -0.519615 0.15 0 -0 0</pose>
        <inertial>
          <mass>0.5</mass>
          <inertia>
            <ixx>0.0045</ixx>
            <iyy>0.0045</iyy>
            <izz>0.0045</izz>
            <ixy>0</ixy>
            <ixz>0</ixz>
            <iyz>0</iyz>
          </inertia>
        </inertial>
        <collision name='collision'>
          <geometry>
            <sphere>
              <radius>0.15</radius>
            </sphere>
          </geometry>
          <surface>
            <contact>
              <ode>
                <kp>1e+08</kp>
                <kd>1</kd>
                <min_depth>0.0005</min_depth>
              </ode>
            </contact>
            <bounce/>
            <friction>
              <torsional>
                <ode/>
              </torsional>
              <ode/>
            </friction>
          </surface>
          <max_contacts>10</max_contacts>
        </collision>
        <visual name='visual'>
          <geometry>
            <sphere>
              <radius>0.15</radius>
            </sphere>
          </geometry>
          <material>
            <script>
              <uri>file://media/materials/scripts/gazebo.material</uri>
              <name>Gazebo/Black</name>
            </script>
          </material>
        </visual>
        <self_collide>0</self_collide>
        <kinematic>0</kinematic>
      </link>
      <joint name='wheel_rear_right_spin' type='revolute'>
        <parent>frame</parent>
        <child>wheel_rear_right</child>
        <axis>
          <xyz>0 1 0</xyz>
          <use_parent_model_frame>0</use_parent_model_frame>
          <limit>
            <lower>-1e+16</lower>
            <upper>1e+16</upper>
          </limit>
          <dynamics>
            <spring_reference>0</spring_reference>
            <spring_stiffness>0</spring_stiffness>
          </dynamics>
        </axis>
      </joint>
      <pose frame=''>7.43698 -8.73706 0 0 -0 0</pose>
    </model>
    <model name='table_marble'>
      <static>1</static>
      <pose frame=''>7.29977 7.98334 0.648 0 -0 0</pose>
      <link name='link'>
        <collision name='collision'>
          <geometry>
            <mesh>
              <uri>model:///table_marble/meshes/table_lightmap.dae</uri>
              <scale>0.25 0.25 0.25</scale>
            </mesh>
          </geometry>
          <max_contacts>10</max_contacts>
          <surface>
            <contact>
              <ode/>
            </contact>
            <bounce/>
            <friction>
              <torsional>
                <ode/>
              </torsional>
              <ode/>
            </friction>
          </surface>
        </collision>
        <visual name='visual'>
          <geometry>
            <mesh>
              <uri>model://table_marble/meshes/table_lightmap.dae</uri>
              <scale>0.25 0.25 0.25</scale>
            </mesh>
          </geometry>
          <material>
            <script>
              <uri>model://table_marble/materials/scripts</uri>
              <uri>model://table_marble/materials/textures</uri>
              <name>Table/Marble_Lightmap</name>
            </script>
            <lighting>0</lighting>
          </material>
        </visual>
        <self_collide>0</self_collide>
        <kinematic>0</kinematic>
      </link>
    </model>
    <model name='Stop Sign'>
      <static>1</static>
      <link name='link'>
        <collision name='collision'>
          <geometry>
            <mesh>
              <uri>model://stop_sign/meshes/stop_sign.dae</uri>
            </mesh>
          </geometry>
          <max_contacts>10</max_contacts>
          <surface>
            <contact>
              <ode/>
            </contact>
            <bounce/>
            <friction>
              <torsional>
                <ode/>
              </torsional>
              <ode/>
            </friction>
          </surface>
        </collision>
        <visual name='visual'>
          <geometry>
            <mesh>
              <uri>model://stop_sign/meshes/stop_sign.dae</uri>
            </mesh>
          </geometry>
          <material>
            <script>
              <uri>model://stop_sign/materials/scripts</uri>
              <uri>model://stop_sign/materials/textures</uri>
              <name>StopSign/Diffuse</name>
            </script>
          </material>
        </visual>
        <self_collide>0</self_collide>
        <kinematic>0</kinematic>
      </link>
      <pose frame=''>8.27709 5.20939 0 0 -0 0</pose>
    </model>
    <model name='stop_light_post'>
      <static>1</static>
      <link name='link'>
        <collision name='post'>
          <geometry>
            <mesh>
              <uri>model://stop_light_post/meshes/stop_light_post.obj</uri>
              <scale>0.01 0.01 0.01</scale>
            </mesh>
          </geometry>
          <max_contacts>10</max_contacts>
          <surface>
            <contact>
              <ode/>
            </contact>
            <bounce/>
            <friction>
              <torsional>
                <ode/>
              </torsional>
              <ode/>
            </friction>
          </surface>
        </collision>
        <visual name='post'>
          <geometry>
            <mesh>
              <uri>model://stop_light_post/meshes/stop_light_post.obj</uri>
              <scale>0.01 0.01 0.01</scale>
            </mesh>
          </geometry>
        </visual>
        <self_collide>0</self_collide>
        <kinematic>0</kinematic>
      </link>
      <static>1</static>
      <link name='right_light::link'>
        <collision name='collision'>
          <geometry>
            <mesh>
              <uri>model://stop_light/meshes/stop_light.obj</uri>
              <scale>0.01 0.01 0.01</scale>
            </mesh>
          </geometry>
          <max_contacts>10</max_contacts>
          <surface>
            <contact>
              <ode/>
            </contact>
            <bounce/>
            <friction>
              <torsional>
                <ode/>
              </torsional>
              <ode/>
            </friction>
          </surface>
        </collision>
        <visual name='frame'>
          <geometry>
            <mesh>
              <uri>model://stop_light/meshes/stop_light.obj</uri>
              <scale>0.01 0.01 0.01</scale>
            </mesh>
          </geometry>
        </visual>
        <visual name='red'>
          <pose frame=''>-0.001123 -0.082251 -0.147514 0 -0 0</pose>
          <geometry>
            <sphere>
              <radius>0.1012</radius>
            </sphere>
          </geometry>
          <material>
            <script>
              <uri>model://stop_light/materials/scripts/</uri>
              <uri>model://stop_light/materials/textures/</uri>
              <name>StopLight/Light</name>
            </script>
            <ambient>1 0 0 1</ambient>
            <specular>1 0 0 1</specular>
          </material>
        </visual>
        <visual name='yellow'>
          <pose frame=''>-0.001123 -0.082251 -0.402 0 -0 0</pose>
          <geometry>
            <sphere>
              <radius>0.1012</radius>
            </sphere>
          </geometry>
          <material>
            <script>
              <uri>model://stop_light/materials/scripts/</uri>
              <uri>model://stop_light/materials/textures/</uri>
              <name>StopLight/Light</name>
            </script>
            <ambient>1 1 0 1</ambient>
            <specular>1 1 0 1</specular>
          </material>
        </visual>
        <visual name='green'>
          <pose frame=''>-0.001123 -0.082251 -0.655 0 -0 0</pose>
          <geometry>
            <sphere>
              <radius>0.1012</radius>
            </sphere>
          </geometry>
          <material>
            <script>
              <uri>model://stop_light/materials/scripts/</uri>
              <uri>model://stop_light/materials/textures/</uri>
              <name>StopLight/Light</name>
            </script>
            <ambient>0 1 0 1</ambient>
            <specular>0 1 0 1</specular>
          </material>
        </visual>
        <pose frame=''>0 -0.05 4 0 -0 0</pose>
        <self_collide>0</self_collide>
        <kinematic>0</kinematic>
      </link>
      <static>1</static>
      <link name='center_light::link'>
        <collision name='collision'>
          <geometry>
            <mesh>
              <uri>model://stop_light/meshes/stop_light.obj</uri>
              <scale>0.01 0.01 0.01</scale>
            </mesh>
          </geometry>
          <max_contacts>10</max_contacts>
          <surface>
            <contact>
              <ode/>
            </contact>
            <bounce/>
            <friction>
              <torsional>
                <ode/>
              </torsional>
              <ode/>
            </friction>
          </surface>
        </collision>
        <visual name='frame'>
          <geometry>
            <mesh>
              <uri>model://stop_light/meshes/stop_light.obj</uri>
              <scale>0.01 0.01 0.01</scale>
            </mesh>
          </geometry>
        </visual>
        <visual name='red'>
          <pose frame=''>-0.001123 -0.082251 -0.147514 0 -0 0</pose>
          <geometry>
            <sphere>
              <radius>0.1012</radius>
            </sphere>
          </geometry>
          <material>
            <script>
              <uri>model://stop_light/materials/scripts/</uri>
              <uri>model://stop_light/materials/textures/</uri>
              <name>StopLight/Light</name>
            </script>
            <ambient>1 0 0 1</ambient>
            <specular>1 0 0 1</specular>
          </material>
        </visual>
        <visual name='yellow'>
          <pose frame=''>-0.001123 -0.082251 -0.402 0 -0 0</pose>
          <geometry>
            <sphere>
              <radius>0.1012</radius>
            </sphere>
          </geometry>
          <material>
            <script>
              <uri>model://stop_light/materials/scripts/</uri>
              <uri>model://stop_light/materials/textures/</uri>
              <name>StopLight/Light</name>
            </script>
            <ambient>1 1 0 1</ambient>
            <specular>1 1 0 1</specular>
          </material>
        </visual>
        <visual name='green'>
          <pose frame=''>-0.001123 -0.082251 -0.655 0 -0 0</pose>
          <geometry>
            <sphere>
              <radius>0.1012</radius>
            </sphere>
          </geometry>
          <material>
            <script>
              <uri>model://stop_light/materials/scripts/</uri>
              <uri>model://stop_light/materials/textures/</uri>
              <name>StopLight/Light</name>
            </script>
            <ambient>0 1 0 1</ambient>
            <specular>0 1 0 1</specular>
          </material>
        </visual>
        <pose frame=''>-2 0.04 5.82 0 -0 0</pose>
        <self_collide>0</self_collide>
        <kinematic>0</kinematic>
      </link>
      <pose frame=''>9.48189 5.98732 0 0 -0 0</pose>
    </model>
  </world>
</sdf>
